Workbook

Sheet TD
A1: TOMADOR | B1: (Vários itens)
A3: MODALIDADE | B3: Contagem de FUNCIONÁRIO | C3: Soma de TOTAL BRUTO + PF
A4: CLT | B4: 61 | C4: 327445.06
A5: ESTÁGIO | B5: 4 | C5: 6056.62
A6: PF | B6: 1 | C6: 9879.83
A7: PJ | B7: 9 | C7: 102840.78
A8: Total Geral | B8: 75 | C8: 446222.29

Sheet Custo_Fopag (2)
A1: FUNCIONARIO | B1: COMPETENCIA | C1: MODALIDADE | D1: EMPRESA | E1: CNPJ | F1: SETOR | G1: SECAO | H1: TOMADOR | I1: ADMISSAO | J1: DEMISSAO | K1: C CUSTO | L1: FUNCAO | M1: SAL. BASE | N1: SAL. PAGO | O1: ATESTADO | P1: SAL.PAGO + ATESTADO | Q1: AUX.MATERNID | R1: FERIAS | S1: ABONO PEC | T1: AD. FUNCAO | U1: AD. INSALUB | V1: AD. PERICUL | W1: GRAT FUNÇÃO 40% | X1: GRAT(ADRIANA) | Y1: ADICTPOSERV | Z1: ADIC NOTURNO | AA1: HRS EXTRAS | AB1: DSR HRS EXTRAS | AC1: COMISSOES | AD1: DSR COMISSOES | AE1: DIF CONVENCAO | AF1: QUEBRA CAIXA | AG1: TT EV TRIB (INSS/IRRF/FGTS) | AH1: P. GRAT G3S | AI1: P.PRODUCAO | AJ1: P.CHECKLIST | AK1: P.PRENSA | AL1: P.PORTA | AM1: P.CONTAINER | AN1: P.OPERADORES | AO1: P.V.UNIDADES | AP1: PREMIOS | AQ1: P ANUAL SETCESP | AR1: TT EV EXCL IRRF | AS1: ESTAGIARIOS | AT1: AJ DE CUSTO | AU1: CESTA BASICA R$ | AV1: DIARIA REF | AW1: DIARIA DIFER | AX1: SAL FAMILIA | AY1: PLANO SAUDE | AZ1: AB EVENTUAL | BA1: PLR | BB1: AJ. ALUGUEL | BC1: P.PROD(ANT) | BD1: P.BON(ANT) | BE1: TT EVENT Ñ TRIBUT | BF1: LIQ RESCISAO | BG1: GUIA RESCISAO | BH1: TOTAL RESCISAO | BI1: TOTAL BRUTO | BJ1: TOTAL DESC | BK1: TOTAL LIQUIDO | BL1: FGTS | BM1: INSS EMPRESA | BN1: RAT | BO1: TERCEIROS | BP1: TOTAL ENCARGOS | BQ1: CUSTO
A2: KAMYLA FERNANDA FORIM | B2: 46082 | C2: Empregado – Geral | D2: G3S FL 08 - LONDRINA | E2: 20.947.332/0008-61 | F2: ADMINISTRATIVO | G2: ATENDIMENTO | H2: SELETIVA LONDRINA | I2: 43903 | K2: 1.2.3.1 ADMINISTRATIVO | L2: AUX ADMINISTRATIVO SENIOR | M2: 2950 | N2: 2950 | O2: 0 | P2: =N2+O2 -> 2950 | Q2: 0 | R2: 0 | S2: 0 | T2: 0 | U2: 0 | V2: 0 | W2: 0 | X2: 0 | Y2: 0 | Z2: 0 | AA2: 311.13 | AB2: 59.83 | AC2: 0 | AD2: 0 | AE2: 0 | AF2: 295 | AG2: 3615.96 | AH2: 0 | AI2: 0 | AJ2: 0 | AK2: 0 | AL2: 0 | AM2: 0 | AN2: 0 | AO2: 529.48 | AP2: 0 | AQ2: 0 | AR2: 529.48 | AS2: 0 | AT2: 0 | AU2: 0 | AV2: 0 | AW2: 0 | AX2: 0 | AY2: 0 | AZ2: 0 | BA2: 0 | BB2: 0 | BC2: 0 | BD2: 0 | BE2: 0 | BF2: 0 | BG2: 0 | BH2: 0 | BI2: 4145.44 | BJ2: 1502.5 | BK2: 2642.94 | BL2: 289.27 | BM2: 723.19 | BN2: 206.32 | BO2: 209.72 | BP2: 1428.5 | BQ2: 5573.94
A3: PAULO VITOR TOOKUNI DE LIMA | B3: 46082 | C3: Empregado – Geral | D3: G3S FL 08 - LONDRINA | E3: 20.947.332/0008-61 | F3: OPERACIONAL | G3: PATIO | H3: SELETIVA LONDRINA | I3: 45027 | K3: 1.2.3.3 OPERACIONAL | L3: GERENTE DE PATIO SENIOR | M3: 3679.83 | N3: 1226.61 | O3: 0 | P3: =N3+O3 -> 1226.61 | Q3: 0 | R3: 5497.23 | S3: 2748.61 | T3: 245.32 | U3: 0 | V3: 367.98 | W3: 0 | X3: 0 | Y3: 0 | Z3: 0 | AA3: 0 | AB3: 0 | AC3: 0 | AD3: 0 | AE3: 0 | AF3: 0 | AG3: 10085.75 | AH3: 0 | AI3: 0 | AJ3: 0 | AK3: 0 | AL3: 0 | AM3: 0 | AN3: 0 | AO3: 529.48 | AP3: 0 | AQ3: 0 | AR3: 529.48 | AS3: 0 | AT3: 0 | AU3: 0 | AV3: 0 | AW3: 0 | AX3: 0 | AY3: 0 | AZ3: 0 | BA3: 0 | BB3: 0 | BC3: 0 | BD3: 0 | BE3: 0 | BF3: 0 | BG3: 0 | BH3: 0 | BI3: 10615.23 | BJ3: 257.59 | BK3: 2111.8 | BL3: 586.97 | BM3: 2017.15 | BN3: 575.49 | BO3: 584.97 | BP3: 3764.58 | BQ3: 14379.81
A4: HERALDO CARVALHO DE SOUZA | B4: 46082 | C4: Empregado – Geral | D4: G3S FL 08 - LONDRINA | E4: 20.947.332/0008-61 | F4: OPERACIONAL | G4: PATIO | H4: SELETIVA LONDRINA | I4: 42205 | L4: OPERADOR MANTENEDOR | M4: 1828 | N4: 0 | O4: 0 | P4: =N4+O4 -> 0 | Q4: 0 | R4: 0 | S4: 0 | T4: 0 | U4: 0 | V4: 0 | W4: 0 | X4: 0 | Y4: 0 | Z4: 0 | AA4: 0 | AB4: 0 | AC4: 0 | AD4: 0 | AE4: 0 | AF4: 0 | AG4: 0 | AH4: 0 | AI4: 0 | AJ4: 0 | AK4: 0 | AL4: 0 | AM4: 0 | AN4: 0 | AO4: 0 | AP4: 0 | AQ4: 0 | AR4: 0 | AS4: 0 | AT4: 0 | AU4: 0 | AV4: 0 | AW4: 0 | AX4: 0 | AY4: 0 | AZ4: 0 | BA4: 0 | BB4: 0 | BC4: 0 | BD4: 0 | BE4: 0 | BF4: 0 | BG4: 0 | BH4: 0 | BI4: 0 | BJ4: 0 | BK4: 0 | BL4: 0 | BM4: 0 | BN4: 0 | BO4: 0 | BP4: 0 | BQ4: 0
A5: LUIS DO CARMO PEREIRA | B5: 46082 | C5: Empregado – Geral | D5: G S MATRIZ - PRES PRUD | E5: 20.504.237/0001-17 | F5: LOGISTICA | G5: TRANSPORTE | H5: SELETIVA PRESIDENTE PRUDENTE | I5: 41883 | L5: MOTORISTA CARRETEIRO | M5: 1710 | N5: 0 | O5: 0 | P5: =N5+O5 -> 0 | Q5: 0 | R5: 0 | S5: 0 | T5: 0 | U5: 0 | V5: 0 | W5: 0 | X5: 0 | Y5: 0 | Z5: 0 | AA5: 0 | AB5: 0 | AC5: 0 | AD5: 0 | AE5: 0 | AF5: 0 | AG5: 0 | AH5: 0 | AI5: 0 | AJ5: 0 | AK5: 0 | AL5: 0 | AM5: 0 | AN5: 0 | AO5: 0 | AP5: 0 | AQ5: 0 | AR5: 0 | AS5: 0 | AT5: 0 | AU5: 0 | AV5: 0 | AW5: 0 | AX5: 0 | AY5: 0 | AZ5: 0 | BA5: 0 | BB5: 0 | BC5: 0 | BD5: 0 | BE5: 0 | BF5: 0 | BG5: 0 | BH5: 0 | BI5: 0 | BJ5: 0 | BK5: 0 | BL5: 0 | BM5: 0 | BN5: 0 | BO5: 0 | BP5: 0 | BQ5: 0
A6: CELIO MATEUS | B6: 46082 | C6: Empregado – Geral | D6: G S MATRIZ - PRES PRUD | E6: 20.504.237/0001-17 | F6: OPERACIONAL | G6: PATIO | H6: SELETIVA PRESIDENTE PRUDENTE | I6: 40269 | K6: 1.2.5.3 OPERACIONAL | L6: OPERADOR MANTENEDOR JR | M6: 2610 | N6: 870 | O6: 0 | P6: =N6+O6 -> 870 | Q6: 0 | R6: 3784.63 | S6: 1892.32 | T6: 174 | U6: 0 | V6: 0 | W6: 0 | X6: 0 | Y6: 43.5 | Z6: 0 | AA6: 88.98 | AB6: 19.77 | AC6: 0 | AD6: 0 | AE6: 0 | AF6: 0 | AG6: 6873.2 | AH6: 0 | AI6: 0 | AJ6: 0 | AK6: 0 | AL6: 0 | AM6: 0 | AN6: 0 | AO6: 579.34 | AP6: 0 | AQ6: 0 | AR6: 579.34 | AS6: 0 | AT6: 0 | AU6: 0 | AV6: 2520 | AW6: 0 | AX6: 0 | AY6: 0 | AZ6: 2175 | BA6: 0 | BB6: 0 | BC6: 0 | BD6: 0 | BE6: 0 | BF6: 0 | BG6: 0 | BH6: 0 | BI6: 12147.54 | BJ6: 3755.32 | BK6: 2715.27 | BL6: 398.47 | BM6: 1374.64 | BN6: 103.09 | BO6: 398.64 | BP6: 2274.84 | BQ6: 14422.38
A7: MARCIO AFONSO | B7: 46082 | C7: Empregado – Geral | D7: G S MATRIZ - PRES PRUD | E7: 20.504.237/0001-17 | F7: LOGISTICA | G7: TRANSPORTE | H7: SELETIVA PRESIDENTE PRUDENTE | I7: 44153 | K7: 1.7.8.4 LOGISTICA | L7: MOTORISTA CARRETEIRO MANTENEDOR SENIOR III | M7: 3287.33 | N7: 3287.33 | O7: 0 | P7: =N7+O7 -> 3287.33 | Q7: 0 | R7: 0 | S7: 0 | T7: 657.47 | U7: 0 | V7: 0 | W7: 0 | X7: 0 | Y7: 164.37 | Z7: 0 | AA7: 834.91 | AB7: 160.56 | AC7: 0 | AD7: 0 | AE7: 0 | AF7: 0 | AG7: 5104.64 | AH7: 0 | AI7: 0 | AJ7: 906.92 | AK7: 0 | AL7: 0 | AM7: 0 | AN7: 0 | AO7: 579.34 | AP7: 0 | AQ7: 0 | AR7: 1486.26 | AS7: 0 | AT7: 0 | AU7: 0 | AV7: 1452 | AW7: 0 | AX7: 0 | AY7: 0 | AZ7: 0 | BA7: 0 | BB7: 0 | BC7: 0 | BD7: 0 | BE7: 0 | BF7: 0 | BG7: 0 | BH7: 0 | BI7: 8042.9 | BJ7: 2052.61 | BK7: 5990.29 | BL7: 408.37 | BM7: 1020.93 | BN7: 76.56 | BO7: 296.06 | BP7: 1801.92 | BQ7: 9844.82
A8: JULIANO VIEIRA DE SANTANA | B8: 46082 | C8: Empregado – Geral | D8: G S MATRIZ - PRES PRUD | E8: 20.504.237/0001-17 | F8: LOGISTICA | G8: TRANSPORTE | H8: SELETIVA CORPORATIVO SUCATA | I8: 42217 | K8: 1.7.8.4 LOGISTICA | L8: MOTORISTA CARRETEIRO MANTENEDOR SENIOR III | M8: 3287.33 | N8: 3287.33 | O8: 0 | P8: =N8+O8 -> 3287.33 | Q8: 0 | R8: 0 | S8: 0 | T8: 657.47 | U8: 0 | V8: 0 | W8: 0 | X8: 0 | Y8: 164.37 | Z8: 0 | AA8: 812.5 | AB8: 156.25 | AC8: 0 | AD8: 0 | AE8: 0 | AF8: 0 | AG8: 5077.92 | AH8: 0 | AI8: 0 | AJ8: 0 | AK8: 0 | AL8: 0 | AM8: 0 | AN8: 0 | AO8: 579.34 | AP8: 0 | AQ8: 0 | AR8: 579.34 | AS8: 0 | AT8: 0 | AU8: 0 | AV8: 2205 | AW8: 0 | AX8: 0 | AY8: 0 | AZ8: 0 | BA8: 0 | BB8: 0 | BC8: 0 | BD8: 0 | BE8: 0 | BF8: 0 | BG8: 0 | BH8: 0 | BI8: 7862.26 | BJ8: 785.37 | BK8: 7076.89 | BL8: 406.23 | BM8: 1015.58 | BN8: 76.16 | BO8: 294.51 | BP8: 1792.48 | BQ8: 9654.74
A9: MONIQUE ISABELE DE LIMA | B9: 46082 | C9: Empregado – Geral | D9: G S MATRIZ - PRES PRUD | E9: 20.504.237/0001-17 | F9: TRANSMOVE | G9: ADMINISTRATIVO | H9: TRANSMOVE GSL | I9: 44274 | K9: 1.4.1.2 ADMINISTRATIVO | L9: ANALISTA ADMINISTRATIVO SENIOR | M9: 2950 | N9: 2950 | O9: 0 | P9: =N9+O9 -> 2950 | Q9: 0 | R9: 0 | S9: 0 | T9: 0 | U9: 0 | V9: 0 | W9: 0 | X9: 0 | Y9: 147.5 | Z9: 0 | AA9: 577.61 | AB9: 111.08 | AC9: 0 | AD9: 0 | AE9: 0 | AF9: 0 | AG9: 3786.19 | AH9: 0 | AI9: 808 | AJ9: 0 | AK9: 0 | AL9: 0 | AM9: 0 | AN9: 0 | AO9: 0 | AP9: 150 | AQ9: 0 | AR9: 958 | AS9: 0 | AT9: 0 | AU9: 0 | AV9: 0 | AW9: 0 | AX9: 0 | AY9: 0 | AZ9: 0 | BA9: 0 | BB9: 0 | BC9: 0 | BD9: 0 | BE9: 0 | BF9: 0 | BG9: 0 | BH9: 0 | BI9: 4744.19 | BJ9: 2203.05 | BK9: 2541.14 | BL9: 302.14 | BM9: 757.24 | BN9: 56.79 | BO9: 219.59 | BP9: 1335.76 | BQ9: 6079.95
A10: THAIS SILVA ROCHA | B10: 46082 | C10: Empregado – Geral | D10: G S MATRIZ - PRES PRUD | E10: 20.504.237/0001-17 | F10: INTRA-LOGISTICA | G10: ADMINISTRATIVO | H10: EKIPA LOCACOES E SERV G&S | I10: 45931 | K10: 1.7.1.1 APOIO | L10: ANALISTA ADMINISTRATIVO OPERACIONAL JUNIOR | M10: 2500 | N10: 2416.67 | O10: 83.33 | P10: =N10+O10 -> 2500 | Q10: 0 | R10: 0 | S10: 0 | T10: 0 | U10: 0 | V10: 0 | W10: 0 | X10: 0 | Y10: 0 | Z10: 0 | AA10: 0 | AB10: 0 | AC10: 0 | AD10: 0 | AE10: 0 | AF10: 0 | AG10: 2500 | AH10: 0 | AI10: 0 | AJ10: 0 | AK10: 0 | AL10: 0 | AM10: 0 | AN10: 0 | AO10: 0 | AP10: 0 | AQ10: 0 | AR10: 0 | AS10: 0 | AT10: 0 | AU10: 0 | AV10: 0 | AW10: 0 | AX10: 0 | AY10: 0 | AZ10: 0 | BA10: 0 | BB10: 0 | BC10: 0 | BD10: 0 | BE10: 0 | BF10: 0 | BG10: 0 | BH10: 0 | BI10: 2500 | BJ10: 225.68 | BK10: 2274.32 | BL10: 200 | BM10: 500 | BN10: 37.5 | BO10: 145 | BP10: 882.5 | BQ10: 3382.5
A11: MARCELO VITOR | B11: 46082 | C11: Empregado – Geral | D11: G S MATRIZ - PRES PRUD | E11: 20.504.237/0001-17 | F11: OPERACIONAL | G11: PATIO | H11: SELETIVA PRESIDENTE PRUDENTE | I11: 43790 | K11: 1.2.5.5 PRENSA FIXA JCG800 | L11: OPERADOR MANTENEDOR SENIOR | M11: 3158.66 | N11: 3158.66 | O11: 0 | P11: =N11+O11 -> 3158.66 | Q11: 0 | R11: 0 | S11: 0 | T11: 631.73 | U11: 0 | V11: 0 | W11: 0 | X11: 0 | Y11: 157.93 | Z11: 0 | AA11: 2010.05 | AB11: 386.55 | AC11: 0 | AD11: 0 | AE11: 0 | AF11: 0 | AG11: 6344.92 | AH11: 0 | AI11: 424.21 | AJ11: 0 | AK11: 0 | AL11: 0 | AM11: 0 | AN11: 0 | AO11: 579.34 | AP11: 0 | AQ11: 0 | AR11: 1003.55 | AS11: 0 | AT11: 0 | AU11: 0 | AV11: 2016 | AW11: 0 | AX11: 0 | AY11: 0 | AZ11: 0 | BA11: 0 | BB11: 0 | BC11: 0 | BD11: 0 | BE11: 0 | BF11: 0 | BG11: 0 | BH11: 0 | BI11: 9364.47 | BJ11: 4366.59 | BK11: 4997.88 | BL11: 507.59 | BM11: 1268.98 | BN11: 95.17 | BO11: 368 | BP11: 2239.74 | BQ11: 11604.21
A12: EDILEUSA PEREIRA LISBOA | B12: 46082 | C12: Empregado – Geral | D12: G S MATRIZ - PRES PRUD | E12: 20.504.237/0001-17 | F12: OPERACIONAL | G12: PATIO | H12: SELETIVA PRESIDENTE PRUDENTE | I12: 46043 | K12: 1.2.5.3 OPERACIONAL | L12: OPERADOR MANTENEDOR JR | M12: 2610 | N12: 2610 | O12: 0 | P12: =N12+O12 -> 2610 | Q12: 0 | R12: 0 | S12: 0 | T12: 522 | U12: 0 | V12: 0 | W12: 0 | X12: 0 | Y12: 0 | Z12: 0 | AA12: 750.61 | AB12: 144.35 | AC12: 0 | AD12: 0 | AE12: 0 | AF12: 0 | AG12: 4026.96 | AH12: 0 | AI12: 0 | AJ12: 0 | AK12: 0 | AL12: 0 | AM12: 0 | AN12: 0 | AO12: 579.34 | AP12: 0 | AQ12: 0 | AR12: 579.34 | AS12: 0 | AT12: 0 | AU12: 0 | AV12: 0 | AW12: 0 | AX12: 0 | AY12: 0 | AZ12: 0 | BA12: 0 | BB12: 0 | BC12: 0 | BD12: 0 | BE12: 0 | BF12: 0 | BG12: 0 | BH12: 0 | BI12: 4606.3 | BJ12: 1451.06 | BK12: 3155.24 | BL12: 322.15 | BM12: 805.39 | BN12: 60.4 | BO12: 233.56 | BP12: 1421.5 | BQ12: 6027.8
A13: MURILO BONI CANDIDO | B13: 46082 | C13: Bolsista - Estagiário | D13: G S MATRIZ - PRES PRUD | E13: 20.504.237/0001-17 | F13: INTRA-LOGISTICA | G13: ADMINISTRATIVO | H13: EKIPA LOCACOES E SERV G&S | I13: 46083 | K13: 1.7.2.1 ADMINISTRATIVO | L13: AUXILIAR DE MARKETING - ESTAGIARIO | M13: 1000 | N13: 0 | O13: 0 | P13: =N13+O13 -> 0 | Q13: 0 | R13: 0 | S13: 0 | T13: 0 | U13: 0 | V13: 0 | W13: 0 | X13: 0 | Y13: 0 | Z13: 0 | AA13: 0 | AB13: 0 | AC13: 0 | AD13: 0 | AE13: 0 | AF13: 0 | AG13: 0 | AH13: 0 | AI13: 0 | AJ13: 0 | AK13: 0 | AL13: 0 | AM13: 0 | AN13: 0 | AO13: 0 | AP13: 0 | AQ13: 0 | AR13: 0 | AS13: 1500 | AT13: 0 | AU13: 0 | AV13: 0 | AW13: 0 | AX13: 0 | AY13: 0 | AZ13: 0 | BA13: 0 | BB13: 0 | BC13: 0 | BD13: 0 | BE13: 0 | BF13: 0 | BG13: 0 | BH13: 0 | BI13: 1500 | BJ13: 250 | BK13: 1250 | BL13: 0 | BM13: 0 | BN13: 0 | BO13: 0 | BP13: 0 | BQ13: 1500
A14: FERNANDO THALLES SOUZA OLIVEIRA | B14: 46082 | C14: Bolsista - Estagiário | D14: G S MATRIZ - PRES PRUD | E14: 20.504.237/0001-17 | F14: INTRA-LOGISTICA | G14: ADMINISTRATIVO | H14: EKIPA LOCACOES E SERV G&S | I14: 46083 | K14: 1.7.2.1 ADMINISTRATIVO | L14: AUXILIAR DE ENGENHARIA - ESTAGIARIO | M14: 1000 | N14: 0 | O14: 0 | P14: =N14+O14 -> 0 | Q14: 0 | R14: 0 | S14: 0 | T14: 0 | U14: 0 | V14: 0 | W14: 0 | X14: 0 | Y14: 0 | Z14: 0 | AA14: 0 | AB14: 0 | AC14: 0 | AD14: 0 | AE14: 0 | AF14: 0 | AG14: 0 | AH14: 0 | AI14: 0 | AJ14: 0 | AK14: 0 | AL14: 0 | AM14: 0 | AN14: 0 | AO14: 0 | AP14: 0 | AQ14: 0 | AR14: 0 | AS14: 1500 | AT14: 0 | AU14: 0 | AV14: 0 | AW14: 0 | AX14: 0 | AY14: 0 | AZ14: 0 | BA14: 0 | BB14: 0 | BC14: 0 | BD14: 0 | BE14: 0 | BF14: 0 | BG14: 0 | BH14: 0 | BI14: 1500 | BJ14: 250 | BK14: 1250 | BL14: 0 | BM14: 0 | BN14: 0 | BO14: 0 | BP14: 0 | BQ14: 1500
A15: PATRICIO SANTANA DA SILVA THEODORO | B15: 46082 | C15: Empregado – Geral | D15: G S FL 04 - MARINGA | E15: 20.504.237/0004-60 | F15: OPERACIONAL | G15: PATIO | H15: SELETIVA MARINGA DISTRITO | I15: 41276 | K15: 1.2.4.3 OPERACIONAL | L15: OPERADOR MANTENEDOR SENIOR | M15: 3354.5 | N15: 3354.5 | O15: 0 | P15: =N15+O15 -> 3354.5 | Q15: 0 | R15: 0 | S15: 0 | T15: 670.9 | U15: 0 | V15: 0 | W15: 0 | X15: 0 | Y15: 0 | Z15: 0 | AA15: 1849.24 | AB15: 355.62 | AC15: 0 | AD15: 0 | AE15: 0 | AF15: 0 | AG15: 6230.26 | AH15: 0 | AI15: 807.76 | AJ15: 0 | AK15: 0 | AL15: 0 | AM15: 0 | AN15: 0 | AO15: 252.45 | AP15: 0 | AQ15: 0 | AR15: 1060.21 | AS15: 0 | AT15: 0 | AU15: 0 | AV15: 0 | AW15: 0 | AX15: 0 | AY15: 0 | AZ15: 0 | BA15: 0 | BB15: 0 | BC15: 0 | BD15: 0 | BE15: 0 | BF15: 0 | BG15: 0 | BH15: 0 | BI15: 7290.47 | BJ15: 2318.8 | BK15: 4971.67 | BL15: 498.42 | BM15: 1246.05 | BN15: 186.9 | BO15: 361.35 | BP15: 2292.72 | BQ15: 9583.19
A16: RUBENS DE ARAUJO MOTA | B16: 46082 | C16: Empregado – Geral | D16: G S FL 04 - MARINGA | E16: 20.504.237/0004-60 | F16: LOGISTICA | G16: TRANSPORTE | H16: SELETIVA MARINGA DISTRITO | I16: 45664 | J16: 46111 | K16: 1.7.7.4 LOGISTICA | L16: MOTORISTA CARRETEIRO MANTENEDOR SENIOR I | M16: 3345 | N16: 0 | O16: 0 | P16: =N16+O16 -> 0 | Q16: 0 | R16: 0 | S16: 0 | T16: 669 | U16: 0 | V16: 0 | W16: 0 | X16: 0 | Y16: 0 | Z16: 0 | AA16: 1996.66 | AB16: 399.33 | AC16: 0 | AD16: 0 | AE16: 0 | AF16: 0 | AG16: 3064.99 | AH16: 0 | AI16: 0 | AJ16: 914.98 | AK16: 0 | AL16: 0 | AM16: 0 | AN16: 0 | AO16: 252.45 | AP16: 0 | AQ16: 0 | AR16: 1167.43 | AS16: 0 | AT16: 500 | AU16: 0 | AV16: 555.64 | AW16: 0 | AX16: 0 | AY16: 0 | AZ16: 0 | BA16: 0 | BB16: 0 | BC16: 0 | BD16: 0 | BE16: 0 | BF16: 20851.68 | BG16: 1107.57 | BH16: 21959.25 | BI16: 5288.06 | BJ16: 22723.58 | BK16: 0 | BL16: 0 | BM16: 613 | BN16: 91.94 | BO16: 177.76 | BP16: 882.7 | BQ16: 6170.76
A17: WILLIAM CRISTIAN LUPION | B17: 46082 | C17: Empregado – Geral | D17: G S FL 04 - MARINGA | E17: 20.504.237/0004-60 | F17: LOGISTICA | G17: TRANSPORTE | H17: SELETIVA MARINGA DISTRITO | I17: 45117 | K17: 1.7.7.4 LOGISTICA | L17: MOTORISTA CARRETEIRO MANTENEDOR SENIOR I | M17: 3345 | N17: 3345 | O17: 0 | P17: =N17+O17 -> 3345 | Q17: 0 | R17: 0 | S17: 0 | T17: 669 | U17: 0 | V17: 0 | W17: 0 | X17: 0 | Y17: 0 | Z17: 2.97 | AA17: 1235.55 | AB17: 237.61 | AC17: 0 | AD17: 0 | AE17: 0 | AF17: 0 | AG17: 5490.13 | AH17: 0 | AI17: 0 | AJ17: 686.3 | AK17: 0 | AL17: 0 | AM17: 0 | AN17: 0 | AO17: 252.45 | AP17: 0 | AQ17: 0 | AR17: 938.75 | AS17: 0 | AT17: 0 | AU17: 0 | AV17: 776.61 | AW17: 0 | AX17: 0 | AY17: 0 | AZ17: 0 | BA17: 0 | BB17: 0 | BC17: 0 | BD17: 0 | BE17: 0 | BF17: 0 | BG17: 0 | BH17: 0 | BI17: 7205.49 | BJ17: 1941.57 | BK17: 5263.92 | BL17: 439.21 | BM17: 1098.03 | BN17: 164.7 | BO17: 318.42 | BP17: 2020.36 | BQ17: 9225.85
A18: FERNANDO FERRAREZI DOS SANTOS | B18: 46082 | C18: Empregado – Geral | D18: G S FL 04 - MARINGA | E18: 20.504.237/0004-60 | F18: LOGISTICA | G18: TRANSPORTE | H18: SELETIVA MARINGA DISTRITO | I18: 46027 | K18: 1.7.7.4 LOGISTICA | L18: MOTORISTA CARRETEIRO MANTENEDOR SENIOR I | M18: 3345 | N18: 3345 | O18: 0 | P18: =N18+O18 -> 3345 | Q18: 0 | R18: 0 | S18: 0 | T18: 669 | U18: 0 | V18: 0 | W18: 0 | X18: 0 | Y18: 0 | Z18: 0 | AA18: 1316.71 | AB18: 253.21 | AC18: 0 | AD18: 0 | AE18: 0 | AF18: 0 | AG18: 5583.92 | AH18: 0 | AI18: 0 | AJ18: 486.37 | AK18: 0 | AL18: 0 | AM18: 0 | AN18: 0 | AO18: 252.45 | AP18: 0 | AQ18: 0 | AR18: 738.82 | AS18: 0 | AT18: 0 | AU18: 0 | AV18: 181.5 | AW18: 0 | AX18: 0 | AY18: 0 | AZ18: 0 | BA18: 0 | BB18: 0 | BC18: 0 | BD18: 0 | BE18: 0 | BF18: 0 | BG18: 0 | BH18: 0 | BI18: 6504.24 | BJ18: 1954.7 | BK18: 4549.54 | BL18: 446.71 | BM18: 1116.78 | BN18: 167.51 | BO18: 323.86 | BP18: 2054.86 | BQ18: 8559.1
A19: JOHNNIS GUANDALINI SCHIAVON | B19: 46082 | C19: Empregado – Geral | D19: G S FL 04 - MARINGA | E19: 20.504.237/0004-60 | F19: OPERACIONAL | G19: PATIO | H19: SELETIVA MARINGA DISTRITO | I19: 45790 | K19: 1.2.4.3 OPERACIONAL | L19: OPERADOR MANTENEDOR JR | M19: 2610 | N19: 2610 | O19: 0 | P19: =N19+O19 -> 2610 | Q19: 0 | R19: 0 | S19: 0 | T19: 522 | U19: 0 | V19: 0 | W19: 0 | X19: 0 | Y19: 0 | Z19: 0 | AA19: 116.67 | AB19: 22.44 | AC19: 0 | AD19: 0 | AE19: 0 | AF19: 0 | AG19: 3271.11 | AH19: 0 | AI19: 0 | AJ19: 0 | AK19: 0 | AL19: 0 | AM19: 0 | AN19: 0 | AO19: 456.6 | AP19: 0 | AQ19: 0 | AR19: 456.6 | AS19: 0 | AT19: 0 | AU19: 0 | AV19: 0 | AW19: 0 | AX19: 0 | AY19: 0 | AZ19: 0 | BA19: 0 | BB19: 0 | BC19: 0 | BD19: 0 | BE19: 0 | BF19: 0 | BG19: 0 | BH19: 0 | BI19: 3727.71 | BJ19: 2031.99 | BK19: 1695.72 | BL19: 261.68 | BM19: 654.22 | BN19: 98.13 | BO19: 189.72 | BP19: 1203.75 | BQ19: 4931.46
A20: ANTONIO APARECIDO FAQUIANO SOBRINHO | B20: 46082 | C20: Empregado – Geral | D20: G S FL 03 - DOURADOS | E20: 20.504.237/0003-89 | F20: LOGISTICA | G20: TRANSPORTE | H20: SELETIVA DOURADOS | I20: 43521 | K20: 1.7.5.4 LOGISTICA | L20: MOTORISTA CARRETEIRO MANTENEDOR SENIOR I | M20: 2690.66 | N20: 2690.66 | O20: 0 | P20: =N20+O20 -> 2690.66 | Q20: 0 | R20: 0 | S20: 0 | T20: 538.13 | U20: 0 | V20: 0 | W20: 0 | X20: 0 | Y20: 0 | Z20: 0 | AA20: 731.61 | AB20: 140.69 | AC20: 0 | AD20: 0 | AE20: 0 | AF20: 0 | AG20: 4101.09 | AH20: 0 | AI20: 0 | AJ20: 445.29 | AK20: 0 | AL20: 0 | AM20: 0 | AN20: 0 | AO20: 600 | AP20: 0 | AQ20: 0 | AR20: 1045.29 | AS20: 0 | AT20: 0 | AU20: 0 | AV20: 1401 | AW20: 0 | AX20: 0 | AY20: 0 | AZ20: 0 | BA20: 0 | BB20: 0 | BC20: 0 | BD20: 0 | BE20: 0 | BF20: 0 | BG20: 0 | BH20: 0 | BI20: 6547.38 | BJ20: 635.16 | BK20: 5912.22 | BL20: 328.08 | BM20: 820.22 | BN20: 123.03 | BO20: 237.86 | BP20: 1509.19 | BQ20: 8056.57
A21: ERNESTO EUGENIO DA SILVA | B21: 46082 | C21: Empregado – Geral | D21: G S FL 03 - DOURADOS | E21: 20.504.237/0003-89 | F21: LOGISTICA | G21: TRANSPORTE | H21: SELETIVA DOURADOS | I21: 45103 | K21: 1.7.5.4 LOGISTICA | L21: MOTORISTA CARRETEIRO MANTENEDOR SENIOR I | M21: 2690.66 | N21: 2690.66 | O21: 0 | P21: =N21+O21 -> 2690.66 | Q21: 0 | R21: 0 | S21: 0 | T21: 538.13 | U21: 0 | V21: 0 | W21: 0 | X21: 0 | Y21: 0 | Z21: 0 | AA21: 953.96 | AB21: 183.45 | AC21: 0 | AD21: 0 | AE21: 0 | AF21: 0 | AG21: 4366.2 | AH21: 0 | AI21: 0 | AJ21: 366.4 | AK21: 0 | AL21: 0 | AM21: 0 | AN21: 0 | AO21: 600 | AP21: 0 | AQ21: 0 | AR21: 966.4 | AS21: 0 | AT21: 0 | AU21: 0 | AV21: 705 | AW21: 0 | AX21: 0 | AY21: 0 | AZ21: 0 | BA21: 0 | BB21: 0 | BC21: 0 | BD21: 0 | BE21: 0 | BF21: 0 | BG21: 0 | BH21: 0 | BI21: 6037.6 | BJ21: 697.63 | BK21: 5339.97 | BL21: 349.29 | BM21: 873.24 | BN21: 130.98 | BO21: 253.23 | BP21: 1606.74 | BQ21: 7644.34
A22: EVERTON BENITES SOBRINHO | B22: 46082 | C22: Empregado – Geral | D22: G S FL 03 - DOURADOS | E22: 20.504.237/0003-89 | F22: LOGISTICA | G22: TRANSPORTE | H22: SELETIVA DOURADOS | I22: 45440 | J22: 46087 | K22: 1.7.5.4 LOGISTICA | L22: MOTORISTA CARRETEIRO MANTENEDOR SENIOR I | M22: 2690.66 | N22: 0 | O22: 0 | P22: =N22+O22 -> 0 | Q22: 0 | R22: 0 | S22: 0 | T22: 107.63 | U22: 0 | V22: 0 | W22: 0 | X22: 0 | Y22: 0 | Z22: 0 | AA22: 244.36 | AB22: 48.87 | AC22: 0 | AD22: 0 | AE22: 0 | AF22: 0 | AG22: 400.86 | AH22: 0 | AI22: 0 | AJ22: 44.69 | AK22: 0 | AL22: 0 | AM22: 0 | AN22: 0 | AO22: 120 | AP22: 0 | AQ22: 0 | AR22: 164.69 | AS22: 0 | AT22: 500 | AU22: 0 | AV22: 0 | AW22: 0 | AX22: 13.51 | AY22: 0 | AZ22: 0 | BA22: 0 | BB22: 0 | BC22: 0 | BD22: 0 | BE22: 0 | BF22: 10378.53 | BG22: 343.25 | BH22: 10721.78 | BI22: 1079.06 | BJ22: 14575.27 | BK22: 0 | BL22: 0 | BM22: 80.17 | BN22: 12.02 | BO22: 23.24 | BP22: 115.43 | BQ22: 1194.49
A23: JOSE MANOEL DOS SANTOS | B23: 46082 | C23: Empregado – Geral | D23: G S FL 03 - DOURADOS | E23: 20.504.237/0003-89 | F23: OPERACIONAL | G23: PATIO | H23: SELETIVA DOURADOS | I23: 44964 | K23: 1.2.2.3 OPERACIONAL | L23: OPERADOR MANTENEDOR JR | M23: 2610 | N23: 2610 | O23: 0 | P23: =N23+O23 -> 2610 | Q23: 0 | R23: 0 | S23: 0 | T23: 515.67 | U23: 0 | V23: 0 | W23: 0 | X23: 0 | Y23: 0 | Z23: 0 | AA23: 1484.67 | AB23: 285.51 | AC23: 0 | AD23: 0 | AE23: 0 | AF23: 0 | AG23: 4895.85 | AH23: 0 | AI23: 0 | AJ23: 0 | AK23: 0 | AL23: 0 | AM23: 0 | AN23: 0 | AO23: 196.71 | AP23: 0 | AQ23: 0 | AR23: 196.71 | AS23: 0 | AT23: 0 | AU23: 0 | AV23: 0 | AW23: 0 | AX23: 0 | AY23: 0 | AZ23: 0 | BA23: 0 | BB23: 0 | BC23: 0 | BD23: 0 | BE23: 0 | BF23: 0 | BG23: 0 | BH23: 0 | BI23: 5092.56 | BJ23: 1655.41 | BK23: 3437.15 | BL23: 389.13 | BM23: 979.17 | BN23: 146.87 | BO23: 283.95 | BP23: 1799.12 | BQ23: 6891.68
A24: DANIEL JUNIOR SANTOS | B24: 46082 | C24: Empregado – Geral | D24: G S FL 05 - BARUERI | E24: 20.504.237/0005-40 | F24: OPERACIONAL | G24: RESENDE - RJ | H24: EKIPA LOCACOES E SERV G&S | I24: 44617 | K24: 1.7.1.2.1 ARCELOR/ RESENDE/R | L24: MOTORISTA CARRETEIRO MANTENEDOR SENIOR III | M24: 3287.33 | N24: 3287.33 | O24: 0 | P24: =N24+O24 -> 3287.33 | Q24: 0 | R24: 0 | S24: 0 | T24: 657.47 | U24: 0 | V24: 0 | W24: 0 | X24: 0 | Y24: 0 | Z24: 106.82 | AA24: 245.65 | AB24: 47.24 | AC24: 0 | AD24: 0 | AE24: 0 | AF24: 0 | AG24: 4344.51 | AH24: 0 | AI24: 0 | AJ24: 0 | AK24: 692.64 | AL24: 0 | AM24: 0 | AN24: 0 | AO24: 0 | AP24: 0 | AQ24: 0 | AR24: 692.64 | AS24: 0 | AT24: 0 | AU24: 0 | AV24: 2730 | AW24: 0 | AX24: 0 | AY24: 0 | AZ24: 0 | BA24: 0 | BB24: 2000 | BC24: 0 | BD24: 0 | BE24: 0 | BF24: 0 | BG24: 0 | BH24: 0 | BI24: 9767.15 | BJ24: 3824.43 | BK24: 5942.72 | BL24: 347.56 | BM24: 868.9 | BN24: 65.16 | BO24: 251.98 | BP24: 1533.6 | BQ24: 11300.75
A25: CRISTIANO LUCAS BACHIO | B25: 46082 | C25: Empregado – Geral | D25: G S FL 05 - BARUERI | E25: 20.504.237/0005-40 | F25: OPERACIONAL | G25: TUPY/JOINVILLE - SC | H25: EKIPA LOCACOES E SERV G&S | I25: 45026 | K25: 1.7.8.1.1 TUPY - JOINVILLE/S | L25: OPERADOR MANTENEDOR PLENO | M25: 2816.11 | N25: 2816.11 | O25: 0 | P25: =N25+O25 -> 2816.11 | Q25: 0 | R25: 0 | S25: 0 | T25: 563.22 | U25: 0 | V25: 0 | W25: 0 | X25: 0 | Y25: 0 | Z25: 20.45 | AA25: 391.69 | AB25: 75.33 | AC25: 0 | AD25: 0 | AE25: 0 | AF25: 0 | AG25: 3866.8 | AH25: 0 | AI25: 0 | AJ25: 0 | AK25: 0 | AL25: 0 | AM25: 0 | AN25: 975 | AO25: 0 | AP25: 0 | AQ25: 0 | AR25: 975 | AS25: 0 | AT25: 0 | AU25: 0 | AV25: 0 | AW25: 0 | AX25: 0 | AY25: 0 | AZ25: 0 | BA25: 0 | BB25: 0 | BC25: 0 | BD25: 0 | BE25: 0 | BF25: 0 | BG25: 0 | BH25: 0 | BI25: 4841.8 | BJ25: 1479.6 | BK25: 3362.2 | BL25: 309.34 | BM25: 773.36 | BN25: 58 | BO25: 224.27 | BP25: 1364.97 | BQ25: 6206.77
A26: JOAO BATISTA RIBEIRO SILVA | B26: 46082 | C26: Empregado – Geral | D26: G S FL 05 - BARUERI | E26: 20.504.237/0005-40 | F26: OPERACIONAL | G26: PATIO | H26: SELETIVA MARINGA DISTRITO | I26: 42826 | K26: 1.2.4.3 OPERACIONAL | L26: OPERADOR MANTENEDOR PLENO | M26: 2816.11 | N26: 2816.11 | O26: 0 | P26: =N26+O26 -> 2816.11 | Q26: 0 | R26: 0 | S26: 0 | T26: 563.22 | U26: 0 | V26: 0 | W26: 0 | X26: 0 | Y26: 0 | Z26: 0 | AA26: 1568.7 | AB26: 301.67 | AC26: 0 | AD26: 0 | AE26: 0 | AF26: 0 | AG26: 5249.7 | AH26: 0 | AI26: 0 | AJ26: 0 | AK26: 0 | AL26: 0 | AM26: 0 | AN26: 0 | AO26: 252.45 | AP26: 0 | AQ26: 0 | AR26: 252.45 | AS26: 0 | AT26: 0 | AU26: 0 | AV26: 2248 | AW26: 0 | AX26: 0 | AY26: 0 | AZ26: 0 | BA26: 0 | BB26: 0 | BC26: 0 | BD26: 0 | BE26: 0 | BF26: 0 | BG26: 0 | BH26: 0 | BI26: 7750.15 | BJ26: 2723.66 | BK26: 5026.49 | BL26: 419.97 | BM26: 1049.94 | BN26: 78.74 | BO26: 304.48 | BP26: 1853.13 | BQ26: 9603.28
A27: MARCOS ANTONIO CLAUDIO | B27: 46082 | C27: Empregado – Geral | D27: G S FL 05 - BARUERI | E27: 20.504.237/0005-40 | F27: OPERACIONAL | G27: ARCELOR/PIRACICABA - SP | H27: EKIPA LOCACOES E SERV G&S | I27: 45742 | K27: 1.7.1.4.1 ARCELOR/PIRACICABA | L27: OPERADOR MANTENEDOR PLENO | M27: 2816.11 | N27: 2816.11 | O27: 0 | P27: =N27+O27 -> 2816.11 | Q27: 0 | R27: 0 | S27: 0 | T27: 563.22 | U27: 0 | V27: 0 | W27: 0 | X27: 0 | Y27: 0 | Z27: 0 | AA27: 1542.98 | AB27: 296.73 | AC27: 0 | AD27: 0 | AE27: 0 | AF27: 0 | AG27: 5219.04 | AH27: 0 | AI27: 0 | AJ27: 0 | AK27: 1903.5 | AL27: 0 | AM27: 0 | AN27: 0 | AO27: 0 | AP27: 0 | AQ27: 0 | AR27: 1903.5 | AS27: 0 | AT27: 0 | AU27: 0 | AV27: 2016 | AW27: 0 | AX27: 0 | AY27: 0 | AZ27: 0 | BA27: 0 | BB27: 0 | BC27: 0 | BD27: 0 | BE27: 0 | BF27: 0 | BG27: 0 | BH27: 0 | BI27: 9138.54 | BJ27: 3034.85 | BK27: 6103.69 | BL27: 417.52 | BM27: 1043.81 | BN27: 78.28 | BO27: 302.7 | BP27: 1842.31 | BQ27: 10980.85
A28: RIVAEL BARRETO DA SILVA | B28: 46082 | C28: Empregado – Geral | D28: G S FL 05 - BARUERI | E28: 20.504.237/0005-40 | F28: OPERACIONAL | G28: TUPY/JOINVILLE - SC | H28: EKIPA LOCACOES E SERV G&S | I28: 44167 | K28: 1.7.8.1.1 TUPY - JOINVILLE/S | L28: OPERADOR MANTENEDOR SENIOR | M28: 3158.66 | N28: 3158.66 | O28: 0 | P28: =N28+O28 -> 3158.66 | Q28: 0 | R28: 0 | S28: 0 | T28: 631.73 | U28: 0 | V28: 0 | W28: 0 | X28: 0 | Y28: 0 | Z28: 0 | AA28: 279.11 | AB28: 53.68 | AC28: 0 | AD28: 0 | AE28: 0 | AF28: 0 | AG28: 4123.18 | AH28: 0 | AI28: 750 | AJ28: 0 | AK28: 0 | AL28: 0 | AM28: 0 | AN28: 0 | AO28: 0 | AP28: 645 | AQ28: 0 | AR28: 1395 | AS28: 0 | AT28: 50 | AU28: 0 | AV28: 0 | AW28: 0 | AX28: 0 | AY28: 0 | AZ28: 0 | BA28: 0 | BB28: 0 | BC28: 0 | BD28: 0 | BE28: 0 | BF28: 0 | BG28: 0 | BH28: 0 | BI28: 5568.18 | BJ28: 581.25 | BK28: 4986.93 | BL28: 329.85 | BM28: 824.64 | BN28: 61.84 | BO28: 239.14 | BP28: 1455.47 | BQ28: 7023.65
A29: ROBERTT FERNANDO SIQUEIRA | B29: 46082 | C29: Empregado – Geral | D29: G S FL 05 - BARUERI | E29: 20.504.237/0005-40 | F29: OPERACIONAL | G29: ARCELOR/BARRA MANSA - RJ | H29: EKIPA LOCACOES E SERV G&S | I29: 45520 | K29: 1.7.1.3.1 ARCELOR/BARRA MANS | L29: OPERADOR MANTENEDOR PLENO | M29: 2816.11 | N29: 2816.11 | O29: 0 | P29: =N29+O29 -> 2816.11 | Q29: 0 | R29: 0 | S29: 0 | T29: 563.22 | U29: 0 | V29: 0 | W29: 0 | X29: 0 | Y29: 0 | Z29: 50.91 | AA29: 0 | AB29: 0 | AC29: 0 | AD29: 0 | AE29: 0 | AF29: 0 | AG29: 3430.24 | AH29: 0 | AI29: 0 | AJ29: 0 | AK29: 0 | AL29: 0 | AM29: 0 | AN29: 893.2 | AO29: 0 | AP29: 0 | AQ29: 0 | AR29: 893.2 | AS29: 0 | AT29: 250 | AU29: 0 | AV29: 0 | AW29: 0 | AX29: 0 | AY29: 0 | AZ29: 0 | BA29: 0 | BB29: 0 | BC29: 0 | BD29: 0 | BE29: 0 | BF29: 0 | BG29: 0 | BH29: 0 | BI29: 4573.44 | BJ29: 1519.19 | BK29: 3054.25 | BL29: 274.41 | BM29: 686.05 | BN29: 51.45 | BO29: 198.95 | BP29: 1210.86 | BQ29: 5784.3
A30: SANDRILEI MOREIRA JUNIOR | B30: 46082 | C30: Empregado – Geral | D30: G S FL 05 - BARUERI | E30: 20.504.237/0005-40 | F30: OPERACIONAL | G30: ARCELOR/BARRA MANSA - RJ | H30: EKIPA LOCACOES E SERV G&S | I30: 45728 | K30: 1.7.1.3.1 ARCELOR/BARRA MANS | L30: OPERADOR MANTENEDOR PLENO | M30: 2816.11 | N30: 2816.11 | O30: 0 | P30: =N30+O30 -> 2816.11 | Q30: 0 | R30: 0 | S30: 0 | T30: 563.22 | U30: 0 | V30: 0 | W30: 0 | X30: 0 | Y30: 0 | Z30: 85.35 | AA30: 195.85 | AB30: 37.66 | AC30: 0 | AD30: 0 | AE30: 0 | AF30: 0 | AG30: 3698.19 | AH30: 0 | AI30: 0 | AJ30: 0 | AK30: 0 | AL30: 0 | AM30: 0 | AN30: 750.6 | AO30: 0 | AP30: 0 | AQ30: 0 | AR30: 750.6 | AS30: 0 | AT30: 250 | AU30: 0 | AV30: 0 | AW30: 0 | AX30: 0 | AY30: 0 | AZ30: 0 | BA30: 0 | BB30: 0 | BC30: 0 | BD30: 0 | BE30: 0 | BF30: 0 | BG30: 0 | BH30: 0 | BI30: 4698.79 | BJ30: 1831.3 | BK30: 2867.49 | BL30: 295.85 | BM30: 739.64 | BN30: 55.47 | BO30: 214.49 | BP30: 1305.45 | BQ30: 6004.24
A31: SILVANO VIEIRA DE SANTANA | B31: 46082 | C31: Empregado – Geral | D31: G S FL 05 - BARUERI | E31: 20.504.237/0005-40 | F31: LOGISTICA | G31: TRANSPORTE | H31: SELETIVA CORPORATIVO SUCATA | I31: 44238 | K31: 1.7.3.3 OPERACIONAL | L31: MOTORISTA CARRETEIRO MANTENEDOR SENIOR III | M31: 3287.33 | N31: 3287.33 | O31: 0 | P31: =N31+O31 -> 3287.33 | Q31: 0 | R31: 0 | S31: 0 | T31: 657.47 | U31: 0 | V31: 0 | W31: 0 | X31: 0 | Y31: 0 | Z31: 0 | AA31: 313.79 | AB31: 60.34 | AC31: 0 | AD31: 0 | AE31: 0 | AF31: 0 | AG31: 4318.93 | AH31: 0 | AI31: 0 | AJ31: 0 | AK31: 1120 | AL31: 0 | AM31: 0 | AN31: 0 | AO31: 0 | AP31: 0 | AQ31: 0 | AR31: 1120 | AS31: 0 | AT31: 0 | AU31: 0 | AV31: 1502 | AW31: 0 | AX31: 0 | AY31: 0 | AZ31: 0 | BA31: 0 | BB31: 0 | BC31: 0 | BD31: 0 | BE31: 0 | BF31: 0 | BG31: 0 | BH31: 0 | BI31: 6940.93 | BJ31: 671.9 | BK31: 6269.03 | BL31: 345.51 | BM31: 863.79 | BN31: 64.78 | BO31: 250.49 | BP31: 1524.57 | BQ31: 8465.5
A32: WALLANCE ALIEL FURTADO | B32: 46082 | C32: Empregado – Geral | D32: G S FL 05 - BARUERI | E32: 20.504.237/0005-40 | F32: OPERACIONAL | G32: ARCELOR/BARRA MANSA - RJ | H32: EKIPA LOCACOES E SERV G&S | I32: 44876 | K32: 1.7.1.3.1 ARCELOR/BARRA MANS | L32: OPERADOR MANTENEDOR SENIOR | M32: 3158.66 | N32: 3158.66 | O32: 0 | P32: =N32+O32 -> 3158.66 | Q32: 0 | R32: 0 | S32: 0 | T32: 631.73 | U32: 0 | V32: 0 | W32: 0 | X32: 0 | Y32: 0 | Z32: 43.61 | AA32: 0 | AB32: 0 | AC32: 0 | AD32: 0 | AE32: 0 | AF32: 0 | AG32: 3834 | AH32: 0 | AI32: 0 | AJ32: 0 | AK32: 0 | AL32: 0 | AM32: 0 | AN32: 742.5 | AO32: 0 | AP32: 0 | AQ32: 0 | AR32: 742.5 | AS32: 0 | AT32: 250 | AU32: 0 | AV32: 0 | AW32: 0 | AX32: 0 | AY32: 0 | AZ32: 0 | BA32: 0 | BB32: 0 | BC32: 0 | BD32: 0 | BE32: 0 | BF32: 0 | BG32: 0 | BH32: 0 | BI32: 4826.5 | BJ32: 1996.26 | BK32: 2830.24 | BL32: 306.72 | BM32: 766.8 | BN32: 57.51 | BO32: 222.37 | BP32: 1353.4 | BQ32: 6179.9
A33: WAGNER APARECIDO DO NASCIMENTO | B33: 46082 | C33: Empregado – Geral | D33: G S FL 05 - BARUERI | E33: 20.504.237/0005-40 | F33: LOGISTICA | G33: PRENSA MOVEL | H33: SELETIVA CORPORATIVO SUCATA | I33: 43858 | K33: 1.7.3.3 OPERACIONAL | L33: MOTORISTA CARRETEIRO MANTENEDOR SENIOR II | M33: 3091.39 | N33: 3091.39 | O33: 0 | P33: =N33+O33 -> 3091.39 | Q33: 0 | R33: 0 | S33: 0 | T33: 618.28 | U33: 0 | V33: 0 | W33: 0 | X33: 0 | Y33: 0 | Z33: 0 | AA33: 646.94 | AB33: 124.41 | AC33: 0 | AD33: 0 | AE33: 0 | AF33: 0 | AG33: 4481.02 | AH33: 0 | AI33: 2205 | AJ33: 0 | AK33: 0 | AL33: 0 | AM33: 0 | AN33: 0 | AO33: 0 | AP33: 250 | AQ33: 0 | AR33: 2455 | AS33: 0 | AT33: 0 | AU33: 0 | AV33: 2730 | AW33: 0 | AX33: 0 | AY33: 0 | AZ33: 0 | BA33: 0 | BB33: 0 | BC33: 0 | BD33: 0 | BE33: 0 | BF33: 0 | BG33: 0 | BH33: 0 | BI33: 9666.02 | BJ33: 1205.41 | BK33: 8460.61 | BL33: 358.48 | BM33: 896.2 | BN33: 67.21 | BO33: 259.89 | BP33: 1581.78 | BQ33: 11247.8
A34: SERGIO LUIZ RIBEIRO | B34: 46082 | C34: Empregado – Geral | D34: G S FL 05 - BARUERI | E34: 20.504.237/0005-40 | F34: OPERACIONAL | G34: RESENDE - RJ | H34: EKIPA LOCACOES E SERV G&S | I34: 45966 | K34: 1.7.1.2.1 ARCELOR/ RESENDE/R | L34: OPERADOR MANTENEDOR SENIOR | M34: 3158.66 | N34: 3158.66 | O34: 0 | P34: =N34+O34 -> 3158.66 | Q34: 0 | R34: 0 | S34: 0 | T34: 631.73 | U34: 0 | V34: 0 | W34: 0 | X34: 0 | Y34: 0 | Z34: 64.03 | AA34: 0 | AB34: 0 | AC34: 0 | AD34: 0 | AE34: 0 | AF34: 0 | AG34: 3854.42 | AH34: 0 | AI34: 0 | AJ34: 0 | AK34: 812.97 | AL34: 0 | AM34: 0 | AN34: 0 | AO34: 0 | AP34: 0 | AQ34: 0 | AR34: 812.97 | AS34: 0 | AT34: 0 | AU34: 0 | AV34: 0 | AW34: 0 | AX34: 0 | AY34: 0 | AZ34: 0 | BA34: 0 | BB34: 0 | BC34: 0 | BD34: 0 | BE34: 0 | BF34: 0 | BG34: 0 | BH34: 0 | BI34: 4667.39 | BJ34: 1714.61 | BK34: 2952.78 | BL34: 308.35 | BM34: 770.88 | BN34: 57.81 | BO34: 223.55 | BP34: 1360.59 | BQ34: 6027.98
... A55: LAYZA PINHEIRO FRANCESQUETTE | B55: 46082 | C55: Empregado – Geral | D55: G3S FL 10 - PRES PRUD | E55: 20.947.332/0010-86 | F55: COMERCIAL | G55: COMERCIAL | H55: SELETIVA CORPORATIVO SUCATA | I55: 45845 | K55: 1.2.1.1 APOIO | L55: ASSISTENTE COMERCIAL | M55: 2098 | N55: 2098 | O55: 0 | P55: =N55+O55 -> 2098 | Q55: 0 | R55: 0 | S55: 0 | T55: 0 | U55: 0 | V55: 0 | W55: 0 | X55: 0 | Y55: 0 | Z55: 0 | AA55: 0 | AB55: 0 | AC55: 0 | AD55: 0 | AE55: 0 | AF55: 0 | AG55: 2098 | AH55: 0 | AI55: 0 | AJ55: 0 | AK55: 0 | AL55: 929.47 | AM55: 0 | AN55: 0 | AO55: 0 | AP55: 0 | AQ55: 0 | AR55: 929.47 | AS55: 0 | AT55: 0 | AU55: 0 | AV55: 0 | AW55: 0 | AX55: 0 | AY55: 0 | AZ55: 0 | BA55: 165.44 | BB55: 0 | BC55: 0 | BD55: 0 | BE55: 0 | BF55: 0 | BG55: 0 | BH55: 0 | BI55: 3192.91 | BJ55: 164.5 | BK55: 3028.41 | BL55: 167.84 | BM55: 419.6 | BN55: 62.94 | BO55: 121.68 | BP55: 772.06 | BQ55: 3964.97
A56: EDUARDO YUICHI CHINMEI | B56: 46082 | C56: Empregado – Geral | D56: G3S FL 10 - PRES PRUD | E56: 20.947.332/0010-86 | F56: COMERCIAL | G56: COMERCIAL | H56: SELETIVA CORPORATIVO SUCATA | I56: 45748 | J56: 46104 | K56: 1.2.1.1 APOIO | L56: ASSISTENTE COMERCIAL | M56: 2098 | N56: 0 | O56: 0 | P56: =N56+O56 -> 0 | Q56: 0 | R56: 0 | S56: 0 | T56: 0 | U56: 0 | V56: 0 | W56: 0 | X56: 0 | Y56: 0 | Z56: 0 | AA56: 0 | AB56: 8.43 | AC56: 0 | AD56: 0 | AE56: 0 | AF56: 0 | AG56: 8.43 | AH56: 0 | AI56: 0 | AJ56: 0 | AK56: 0 | AL56: 929.47 | AM56: 0 | AN56: 0 | AO56: 0 | AP56: 0 | AQ56: 0 | AR56: 929.47 | AS56: 0 | AT56: 416.67 | AU56: 0 | AV56: 0 | AW56: 0 | AX56: 0 | AY56: 0 | AZ56: 0 | BA56: 165.44 | BB56: 0 | BC56: 0 | BD56: 0 | BE56: 0 | BF56: 6606.85 | BG56: 327.54 | BH56: 6934.39 | BI56: 1520.01 | BJ56: 7625.87 | BK56: 0 | BL56: 0 | BM56: 1.69 | BN56: 0.25 | BO56: 0.48 | BP56: 2.42 | BQ56: 1522.43
A57: MARIANA SIQUEIRA | B57: 46082 | C57: Empregado – Geral | D57: G3S FL 10 - PRES PRUD | E57: 20.947.332/0010-86 | F57: COMERCIAL | G57: COMERCIAL | H57: SELETIVA CORPORATIVO SUCATA | I57: 46055 | K57: 1.2.1.1 APOIO | L57: ASSISTENTE COMERCIAL | M57: 2098 | N57: 2098 | O57: 0 | P57: =N57+O57 -> 2098 | Q57: 0 | R57: 0 | S57: 0 | T57: 0 | U57: 0 | V57: 0 | W57: 0 | X57: 0 | Y57: 0 | Z57: 0 | AA57: 0 | AB57: 0 | AC57: 0 | AD57: 0 | AE57: 0 | AF57: 0 | AG57: 2098 | AH57: 0 | AI57: 0 | AJ57: 0 | AK57: 0 | AL57: 929.47 | AM57: 0 | AN57: 0 | AO57: 0 | AP57: 0 | AQ57: 0 | AR57: 929.47 | AS57: 0 | AT57: 0 | AU57: 0 | AV57: 0 | AW57: 0 | AX57: 0 | AY57: 0 | AZ57: 0 | BA57: 0 | BB57: 0 | BC57: 0 | BD57: 0 | BE57: 0 | BF57: 0 | BG57: 0 | BH57: 0 | BI57: 3027.47 | BJ57: 164.5 | BK57: 2862.97 | BL57: 167.84 | BM57: 419.6 | BN57: 62.94 | BO57: 121.68 | BP57: 772.06 | BQ57: 3799.53
A58: PEDRO MARQUES GUARNIERI | B58: 46082 | C58: Bolsista - Estagiário | D58: G3S FL 10 - PRES PRUD | E58: 20.947.332/0010-86 | F58: ADMINISTRATIVO | G58: QUALIDADE | H58: PILARES | I58: 45790 | J58: 46101 | K58: 1.1.5 QUALIDADE | L58: AUXILIAR ADMINISTRATIVO - ESTAGIARIO(A) | M58: 1000 | N58: 0 | O58: 0 | P58: =N58+O58 -> 0 | Q58: 0 | R58: 0 | S58: 0 | T58: 0 | U58: 0 | V58: 0 | W58: 0 | X58: 0 | Y58: 0 | Z58: 0 | AA58: 0 | AB58: 0 | AC58: 0 | AD58: 0 | AE58: 0 | AF58: 0 | AG58: 0 | AH58: 0 | AI58: 0 | AJ58: 0 | AK58: 0 | AL58: 0 | AM58: 0 | AN58: 0 | AO58: 0 | AP58: 0 | AQ58: 0 | AR58: 0 | AS58: 666.67 | AT58: 0 | AU58: 0 | AV58: 0 | AW58: 0 | AX58: 0 | AY58: 0 | AZ58: 0 | BA58: 0 | BB58: 0 | BC58: 0 | BD58: 0 | BE58: 0 | BF58: 900 | BG58: 0 | BH58: 900 | BI58: 666.67 | BJ58: 900 | BK58: 0 | BL58: 0 | BM58: 0 | BN58: 0 | BO58: 0 | BP58: 0 | BQ58: 666.67
A59: GABRIEL SATOSHI DA SILVA SAKATA | B59: 46082 | C59: Bolsista - Estagiário | D59: G3S FL 10 - PRES PRUD | E59: 20.947.332/0010-86 | F59: ADMINISTRATIVO | G59: SUPRIMENTOS | H59: PILARES | I59: 45810 | K59: 1.1.14 SUPRIMENTOS | L59: AUXILIAR ADMINISTRATIVO - ESTAGIARIO(A) | M59: 1000 | N59: 0 | O59: 0 | P59: =N59+O59 -> 0 | Q59: 0 | R59: 0 | S59: 0 | T59: 0 | U59: 0 | V59: 0 | W59: 0 | X59: 0 | Y59: 0 | Z59: 0 | AA59: 0 | AB59: 0 | AC59: 0 | AD59: 0 | AE59: 0 | AF59: 0 | AG59: 0 | AH59: 0 | AI59: 0 | AJ59: 0 | AK59: 0 | AL59: 0 | AM59: 0 | AN59: 0 | AO59: 0 | AP59: 0 | AQ59: 0 | AR59: 0 | AS59: 1000 | AT59: 0 | AU59: 0 | AV59: 0 | AW59: 0 | AX59: 0 | AY59: 0 | AZ59: 0 | BA59: 0 | BB59: 0 | BC59: 0 | BD59: 0 | BE59: 0 | BF59: 0 | BG59: 0 | BH59: 0 | BI59: 1000 | BJ59: 0 | BK59: 1000 | BL59: 0 | BM59: 0 | BN59: 0 | BO59: 0 | BP59: 0 | BQ59: 1000
A60: MELISSA DE FREITAS ORRIGO | B60: 46082 | C60: Bolsista - Estagiário | D60: G3S FL 10 - PRES PRUD | E60: 20.947.332/0010-86 | F60: COMERCIAL | G60: COMERCIAL | H60: SELETIVA CORPORATIVO SUCATA | I60: 45824 | K60: 1.2.1.1 APOIO | L60: AUXILIAR COMERCIAL - ESTAGIARIO | M60: 1000 | N60: 0 | O60: 0 | P60: =N60+O60 -> 0 | Q60: 0 | R60: 0 | S60: 0 | T60: 0 | U60: 0 | V60: 0 | W60: 0 | X60: 0 | Y60: 0 | Z60: 0 | AA60: 0 | AB60: 0 | AC60: 0 | AD60: 0 | AE60: 0 | AF60: 0 | AG60: 0 | AH60: 0 | AI60: 0 | AJ60: 0 | AK60: 0 | AL60: 0 | AM60: 0 | AN60: 0 | AO60: 0 | AP60: 0 | AQ60: 0 | AR60: 0 | AS60: 1000 | AT60: 0 | AU60: 0 | AV60: 0 | AW60: 0 | AX60: 0 | AY60: 0 | AZ60: 0 | BA60: 0 | BB60: 0 | BC60: 0 | BD60: 0 | BE60: 0 | BF60: 0 | BG60: 0 | BH60: 0 | BI60: 1000 | BJ60: 0 | BK60: 1000 | BL60: 0 | BM60: 0 | BN60: 0 | BO60: 0 | BP60: 0 | BQ60: 1000
...

Sheet BASE+TOMADOR
A1: FUNCIONÁRIO | B1: COMPETÊNCIA | C1: MODALIDADE | D1: EMPRESA | E1: FILIAL | F1: EMPRESA + FILIAL | G1: CNPJ | H1: SETOR | I1: SEÇÃO | J1: TOMADOR | K1: ADMISSÃO | L1: DEMISSÃO | M1: RESPONSÁVEL | N1: CENTRO DE CUSTO | O1: FUNÇÃO | P1: SAL. BASE | Q1: SALÁRIO | R1: AUX. MATERNIDADE | S1: FÉRIAS | T1: AD. FUNÇÃO 20% | U1: AD. INSALUBRIDADE 20% | V1: AD. PERICULOSIDADE 30% | W1: GRATIFICAÇÃO 40% | X1: GRAT(ADRIANA) | Y1: BIÊNIO 5% | Z1: AD. NOTURNO 20% | AA1: HORA EXTRA | AB1: H. EXTRA DSR | AC1: COMISSÃO | AD1: COMISSÃO DSR | AE1: DIF. CONVENÇÃO | AF1: QUEBRA DE CAIXA | AG1: TOTAL EVENTOS COM IMPOSTOS | AH1: ESTAGIARIOS | AI1: AJUDA CUSTO VT | AJ1: CESTA BASICA DINHEIRO | AK1: CESTA BASICA PRODUTO | AL1: PRODUÇÃO FIXO | AM1: PRODUÇÃO CHECK LIST MOTORISTA | AN1: PRODUÇÃO PRENSA | AO1: CAÇAMBA/CONTAINER | AP1: PRÊMIO FIXO | AQ1: PRÊMIO OPERADORES | AR1: PRÊMIO VENDAS UNIDADES | AS1: PRÊMIO PORTA | AT1: PRÊMIO ANUÊNIO | AU1: REFEIÇÃO | AV1: DIÁRIA DIFERENCIADA | AW1: ABONO PECUNIÁRIO FÉRIAS | AX1: SALÁRIO FAMÍLIA | AY1: PLANO DE SAÚDE | AZ1: ASSISTÊNCIA SAÚDE | BA1: AJUDA DE ALUGUEL | BB1: PREMIO GRATIFICAÇÃO | BC1: TOTAL EVENTOS SEM IMPOSTOS | BD1: TOTAL BRUTO | BE1: SALÁRIO PF | BF1: TOTAL BRUTO + PF | BG1: PROV. 13º | BH1: PROV. FÉRIAS | BI1: PROV. 1/3 FERIAS | BJ1: TOTAL PROVISÕES | BK1: INSS | BL1: RAT | BM1: TERCEIROS | BN1: FGTS | BO1: TOTAL ENCARGOS | BP1: TOTAL CUSTO FOLHA (SEM PROVISÕES, COM ENCARGOS) | BQ1: TOTAL GERAL (COM PROVISÕES E ENCARGOS) | BR1: TOTAL RESCISAO | BS1: STATUS
A2: ADEMIR DOS SANTOS | B2: 46082 | C2: CLT | D2: =VLOOKUP(A2,'Custo_Fopag (2)'!A:$BQ,4,0) -> G3S FL 11 - MARINGA | G2: =VLOOKUP(A2,'Custo_Fopag (2)'!$A:$BQ,5,0) -> 20.947.332/0011-67 | H2: =VLOOKUP(A2,'Custo_Fopag (2)'!$A:$BQ,6,0) -> OPERACIONAL | I2: =VLOOKUP(A2,'Custo_Fopag (2)'!$A:$BQ,7,0) -> PATIO | J2: =VLOOKUP(A2,'Custo_Fopag (2)'!$A:$BQ,8,0) -> SELETIVA MARINGA CIDADE ALTA | K2: =VLOOKUP(A2,'Custo_Fopag (2)'!$A:$BQ,9,0) -> 45915 | N2: =VLOOKUP(A2,'Custo_Fopag (2)'!$A:$BQ,11,0) -> 1.2.8.3. OPERACIONAL | O2: =VLOOKUP(A2,'Custo_Fopag (2)'!$A:$BQ,12,0) -> AUXILIAR DE PATIO SENIOR | P2: =VLOOKUP(A2,'Custo_Fopag (2)'!$A:$BQ,13,0) -> 2600 | Q2: =VLOOKUP(A2,'Custo_Fopag (2)'!$A:$BQ,16,0) -> 2600 | R2: =VLOOKUP(A2,'Custo_Fopag (2)'!$A:$BQ,17,0) -> 0 | S2: =VLOOKUP(A2,'Custo_Fopag (2)'!$A:$BP,18,0) -> 0 | T2: =VLOOKUP(A2,'Custo_Fopag (2)'!$A:$BQ,20,0) -> 0 | U2: =VLOOKUP(A2,'Custo_Fopag (2)'!$A:$BQ,21,0) -> 0 | V2: =VLOOKUP(A2,'Custo_Fopag (2)'!$A:$BQ,22,0) -> 0 | W2: =VLOOKUP(A2,'Custo_Fopag (2)'!$A:$BQ,23,0) -> 0 | X2: =VLOOKUP(A2,'Custo_Fopag (2)'!$A:$BQ,24,0) -> 0 | Y2: =VLOOKUP(A2,'Custo_Fopag (2)'!$A:$BQ,25,0) -> 0 | Z2: =VLOOKUP(A2,'Custo_Fopag (2)'!$A:$BQ,26,0) -> 0 | AA2: =VLOOKUP(A2,'Custo_Fopag (2)'!$A:$BQ,27,0) -> 79.95 | AB2: =VLOOKUP(A2,'Custo_Fopag (2)'!$A:$BQ,28,0) -> 15.38 | AC2: =VLOOKUP(A2,'Custo_Fopag (2)'!$A:$BQ,29,0) -> 0 | AD2: =VLOOKUP(A2,'Custo_Fopag (2)'!$A:$BQ,30,0) -> 0 | AE2: =VLOOKUP(A2,'Custo_Fopag (2)'!$A:$BQ,31,0) -> 0 | AF2: =VLOOKUP(A2,'Custo_Fopag (2)'!$A:$BQ,32,0) -> 0 | AG2: =SUM(Q2:AF2) -> 2695.33 | AH2: =VLOOKUP(A2,'Custo_Fopag (2)'!$A:$BQ,45,0) -> 0 | AI2: =_xlfn.XLOOKUP(A2,Beneficios!A:A,Beneficios!B:B,0,0,1) -> 512.87 | AJ2: =VLOOKUP(A2,'Custo_Fopag (2)'!$A:$BQ,47,0) -> 0 | AK2: 0 | AL2: =VLOOKUP(A2,'Custo_Fopag (2)'!$A:$BQ,35,0) -> 0 | AM2: =VLOOKUP(A2,'Custo_Fopag (2)'!$A:$BQ,36,0) -> 0 | AN2: =VLOOKUP(A2,'Custo_Fopag (2)'!$A:$BQ,37,0) -> 0 | AO2: =VLOOKUP(A2,'Custo_Fopag (2)'!$A:$BQ,39,0) -> 0 | AP2: =VLOOKUP(A2,'Custo_Fopag (2)'!$A:$BQ,42,0) -> 0 | AQ2: =VLOOKUP(A2,'Custo_Fopag (2)'!$A:$BQ,40,0) -> 0 | AR2: =VLOOKUP(A2,'Custo_Fopag (2)'!$A:$BQ,41,0) -> 456.6 | AS2: =VLOOKUP(A2,'Custo_Fopag (2)'!$A:$BQ,38,0) -> 0 | AT2: =VLOOKUP(A2,'Custo_Fopag (2)'!$A:$BQ,43,0) -> 0 | AU2: =VLOOKUP(A2,'Custo_Fopag (2)'!$A:$BQ,48,0) -> 0 | AV2: =VLOOKUP(A2,'Custo_Fopag (2)'!$A:$BQ,49,0) -> 0 | AW2: =VLOOKUP(A2,'Custo_Fopag (2)'!$A:$BQ,19,0) -> 0 | AX2: =VLOOKUP(A2,'Custo_Fopag (2)'!$A:$BQ,50,0) -> 0 | AY2: =VLOOKUP(A2,'Custo_Fopag (2)'!$A:$BQ,51,0) -> 0 | AZ2: 0 | BA2: =VLOOKUP(A2,'Custo_Fopag (2)'!$A:$BQ,54,0) -> 0 | BB2: =VLOOKUP(A2,'Custo_Fopag (2)'!$A:$BQ,52,0) -> 0 | BC2: =SUM(AH2:BB2) -> 969.47 | BD2: =BC2+AG2 -> 3664.8 | BF2: =BD2+BE2 -> 3664.8 | BG2: =AG2/12 -> 224.61083 | BH2: =BG2 -> 224.61083 | BI2: =BH2/3 -> 74.870278 | BJ2: =SUM(BG2:BI2) -> 524.09194 | BK2: =VLOOKUP(A2,'Custo_Fopag (2)'!$A:$BQ,65,0) -> 539.07 | BL2: =VLOOKUP(A2,'Custo_Fopag (2)'!$A:$BQP,66,0) -> 80.85 | BM2: =VLOOKUP(A2,'Custo_Fopag (2)'!$A:$BQ,67,0) -> 156.32 | BN2: =VLOOKUP(A2,'Custo_Fopag (2)'!$A:$BQ,64,0) -> 215.62 | BO2: =SUM(BK2:BN2) -> 991.86 | BP2: =BF2+BO2 -> 4656.66 | BQ2: =BF2+BJ2+BO2 -> 5180.7519 | BR2: =VLOOKUP(A2,'Custo_Fopag (2)'!$A:$BQ,60,0) -> 0 | BS2: =IF(ISBLANK(L2),"Ativo","Desligado") -> Ativo
A3: ADRIANA APARECIDA GUABERTO PALANCIO | B3: 46082 | C3: CLT | D3: =VLOOKUP(A3,'Custo_Fopag (2)'!A:$BQ,4,0) -> G3S FL 05 - PRES PRUD | G3: =VLOOKUP(A3,'Custo_Fopag (2)'!$A:$BQ,5,0) -> 20.947.332/0005-19 | H3: =VLOOKUP(A3,'Custo_Fopag (2)'!$A:$BQ,6,0) -> ADMINISTRATIVO | I3: =VLOOKUP(A3,'Custo_Fopag (2)'!$A:$BQ,7,0) -> FINANCEIRO | J3: =VLOOKUP(A3,'Custo_Fopag (2)'!$A:$BQ,8,0) -> SELETIVA CORPORATIVO SUCATA | K3: =VLOOKUP(A3,'Custo_Fopag (2)'!$A:$BQ,9,0) -> 43866 | N3: =VLOOKUP(A3,'Custo_Fopag (2)'!$A:$BQ,11,0) -> 1.2.1.1 APOIO | O3: =VLOOKUP(A3,'Custo_Fopag (2)'!$A:$BQ,12,0) -> ANALISTA FINANCEIRO SENIOR I | P3: =VLOOKUP(A3,'Custo_Fopag (2)'!$A:$BQ,13,0) -> 3500 | Q3: =VLOOKUP(A3,'Custo_Fopag (2)'!$A:$BQ,16,0) -> 3500 | R3: =VLOOKUP(A3,'Custo_Fopag (2)'!$A:$BQ,17,0) -> 0 | S3: =VLOOKUP(A3,'Custo_Fopag (2)'!$A:$BP,18,0) -> 0 | T3: =VLOOKUP(A3,'Custo_Fopag (2)'!$A:$BQ,20,0) -> 0 | U3: =VLOOKUP(A3,'Custo_Fopag (2)'!$A:$BQ,21,0) -> 0 | V3: =VLOOKUP(A3,'Custo_Fopag (2)'!$A:$BQ,22,0) -> 0 | W3: =VLOOKUP(A3,'Custo_Fopag (2)'!$A:$BQ,23,0) -> 0 | X3: =VLOOKUP(A3,'Custo_Fopag (2)'!$A:$BQ,24,0) -> 0 | Y3: =VLOOKUP(A3,'Custo_Fopag (2)'!$A:$BQ,25,0) -> 0 | Z3: =VLOOKUP(A3,'Custo_Fopag (2)'!$A:$BQ,26,0) -> 0 | AA3: =VLOOKUP(A3,'Custo_Fopag (2)'!$A:$BQ,27,0) -> 0 | AB3: =VLOOKUP(A3,'Custo_Fopag (2)'!$A:$BQ,28,0) -> 0 | AC3: =VLOOKUP(A3,'Custo_Fopag (2)'!$A:$BQ,29,0) -> 0 | AD3: =VLOOKUP(A3,'Custo_Fopag (2)'!$A:$BQ,30,0) -> 0 | AE3: =VLOOKUP(A3,'Custo_Fopag (2)'!$A:$BQ,31,0) -> 0 | AF3: =VLOOKUP(A3,'Custo_Fopag (2)'!$A:$BQ,32,0) -> 0 | AG3: =SUM(Q3:AF3) -> 3500 | AH3: =VLOOKUP(A3,'Custo_Fopag (2)'!$A:$BQ,45,0) -> 0 | AI3: =_xlfn.XLOOKUP(A3,Beneficios!A:A,Beneficios!B:B,0,0,1) -> 521.87 | AJ3: =VLOOKUP(A3,'Custo_Fopag (2)'!$A:$BQ,47,0) -> 0 | AK3: 0 | AL3: =VLOOKUP(A3,'Custo_Fopag (2)'!$A:$BQ,35,0) -> 0 | AM3: =VLOOKUP(A3,'Custo_Fopag (2)'!$A:$BQ,36,0) -> 0 | AN3: =VLOOKUP(A3,'Custo_Fopag (2)'!$A:$BQ,37,0) -> 0 | AO3: =VLOOKUP(A3,'Custo_Fopag (2)'!$A:$BQ,39,0) -> 0 | AP3: =VLOOKUP(A3,'Custo_Fopag (2)'!$A:$BQ,42,0) -> 0 | AQ3: =VLOOKUP(A3,'Custo_Fopag (2)'!$A:$BQ,40,0) -> 0 | AR3: =VLOOKUP(A3,'Custo_Fopag (2)'!$A:$BQ,41,0) -> 0 | AS3: =VLOOKUP(A3,'Custo_Fopag (2)'!$A:$BQ,38,0) -> 0 | AT3: =VLOOKUP(A3,'Custo_Fopag (2)'!$A:$BQ,43,0) -> 0 | AU3: =VLOOKUP(A3,'Custo_Fopag (2)'!$A:$BQ,48,0) -> 0 | AV3: =VLOOKUP(A3,'Custo_Fopag (2)'!$A:$BQ,49,0) -> 0 | AW3: =VLOOKUP(A3,'Custo_Fopag (2)'!$A:$BQ,19,0) -> 0 | AX3: =VLOOKUP(A3,'Custo_Fopag (2)'!$A:$BQ,50,0) -> 0 | AY3: =VLOOKUP(A3,'Custo_Fopag (2)'!$A:$BQ,51,0) -> 0 | AZ3: 0 | BA3: =VLOOKUP(A3,'Custo_Fopag (2)'!$A:$BQ,54,0) -> 0 | BB3: =VLOOKUP(A3,'Custo_Fopag (2)'!$A:$BQ,52,0) -> 0 | BC3: =SUM(AH3:BB3) -> 521.87 | BD3: =BC3+AG3 -> 4021.87 | BF3: =BD3+BE3 -> 4021.87 | BG3: =AG3/12 -> 291.66667 | BH3: =BG3 -> 291.66667 | BI3: =BH3/3 -> 97.222222 | BJ3: =SUM(BG3:BI3) -> 680.55556 | BK3: =VLOOKUP(A3,'Custo_Fopag (2)'!$A:$BQ,65,0) -> 700 | BL3: =VLOOKUP(A3,'Custo_Fopag (2)'!$A:$BQP,66,0) -> 52.5 | BM3: =VLOOKUP(A3,'Custo_Fopag (2)'!$A:$BQ,67,0) -> 203 | BN3: =VLOOKUP(A3,'Custo_Fopag (2)'!$A:$BQ,64,0) -> 280 | BO3: =SUM(BK3:BN3) -> 1235.5 | BP3: =BF3+BO3 -> 5257.37 | BQ3: =BF3+BJ3+BO3 -> 5937.9256 | BR3: =VLOOKUP(A3,'Custo_Fopag (2)'!$A:$BQ,60,0) -> 0 | BS3: =IF(ISBLANK(L3),"Ativo","Desligado") -> Ativo
A4: ADRIANA CANDIDO FIGUEIREDO | B4: 46082 | C4: CLT | D4: =VLOOKUP(A4,'Custo_Fopag (2)'!A:$BQ,4,0) -> G3S FL 10 - PRES PRUD | G4: =VLOOKUP(A4,'Custo_Fopag (2)'!$A:$BQ,5,0) -> 20.947.332/0010-86 | H4: =VLOOKUP(A4,'Custo_Fopag (2)'!$A:$BQ,6,0) -> GESTÃO DE GENTE | I4: =VLOOKUP(A4,'Custo_Fopag (2)'!$A:$BQ,7,0) -> DEPTO PESSOAL | J4: =VLOOKUP(A4,'Custo_Fopag (2)'!$A:$BQ,8,0) -> PILARES | K4: =VLOOKUP(A4,'Custo_Fopag (2)'!$A:$BQ,9,0) -> 43692 | N4: =VLOOKUP(A4,'Custo_Fopag (2)'!$A:$BQ,11,0) -> 1.1.10 PESSOAS | O4: =VLOOKUP(A4,'Custo_Fopag (2)'!$A:$BQ,12,0) -> ANALISTA DE DEPTO PESSOAL | P4: =VLOOKUP(A4,'Custo_Fopag (2)'!$A:$BQ,13,0) -> 4568.75 | Q4: =VLOOKUP(A4,'Custo_Fopag (2)'!$A:$BQ,16,0) -> 4568.75 | R4: =VLOOKUP(A4,'Custo_Fopag (2)'!$A:$BQ,17,0) -> 0 | S4: =VLOOKUP(A4,'Custo_Fopag (2)'!$A:$BP,18,0) -> 0 | T4: =VLOOKUP(A4,'Custo_Fopag (2)'!$A:$BQ,20,0) -> 0 | U4: =VLOOKUP(A4,'Custo_Fopag (2)'!$A:$BQ,21,0) -> 0 | V4: =VLOOKUP(A4,'Custo_Fopag (2)'!$A:$BQ,22,0) -> 0 | W4: =VLOOKUP(A4,'Custo_Fopag (2)'!$A:$BQ,23,0) -> 0 | X4: =VLOOKUP(A4,'Custo_Fopag (2)'!$A:$BQ,24,0) -> 0 | Y4: =VLOOKUP(A4,'Custo_Fopag (2)'!$A:$BQ,25,0) -> 0 | Z4: =VLOOKUP(A4,'Custo_Fopag (2)'!$A:$BQ,26,0) -> 0 | AA4: =VLOOKUP(A4,'Custo_Fopag (2)'!$A:$BQ,27,0) -> 0 | AB4: =VLOOKUP(A4,'Custo_Fopag (2)'!$A:$BQ,28,0) -> 0 | AC4: =VLOOKUP(A4,'Custo_Fopag (2)'!$A:$BQ,29,0) -> 0 | AD4: =VLOOKUP(A4,'Custo_Fopag (2)'!$A:$BQ,30,0) -> 0 | AE4: =VLOOKUP(A4,'Custo_Fopag (2)'!$A:$BQ,31,0) -> 0 | AF4: =VLOOKUP(A4,'Custo_Fopag (2)'!$A:$BQ,32,0) -> 0 | AG4: =SUM(Q4:AF4) -> 4568.75 | AH4: =VLOOKUP(A4,'Custo_Fopag (2)'!$A:$BQ,45,0) -> 0 | AI4: =_xlfn.XLOOKUP(A4,Beneficios!A:A,Beneficios!B:B,0,0,1) -> 512.87 | AJ4: =VLOOKUP(A4,'Custo_Fopag (2)'!$A:$BQ,47,0) -> 0 | AK4: 0 | AL4: =VLOOKUP(A4,'Custo_Fopag (2)'!$A:$BQ,35,0) -> 0 | AM4: =VLOOKUP(A4,'Custo_Fopag (2)'!$A:$BQ,36,0) -> 0 | AN4: =VLOOKUP(A4,'Custo_Fopag (2)'!$A:$BQ,37,0) -> 0 | AO4: =VLOOKUP(A4,'Custo_Fopag (2)'!$A:$BQ,39,0) -> 0 | AP4: =VLOOKUP(A4,'Custo_Fopag (2)'!$A:$BQ,42,0) -> 0 | AQ4: =VLOOKUP(A4,'Custo_Fopag (2)'!$A:$BQ,40,0) -> 0 | AR4: =VLOOKUP(A4,'Custo_Fopag (2)'!$A:$BQ,41,0) -> 0 | AS4: =VLOOKUP(A4,'Custo_Fopag (2)'!$A:$BQ,38,0) -> 0 | AT4: =VLOOKUP(A4,'Custo_Fopag (2)'!$A:$BQ,43,0) -> 0 | AU4: =VLOOKUP(A4,'Custo_Fopag (2)'!$A:$BQ,48,0) -> 0 | AV4: =VLOOKUP(A4,'Custo_Fopag (2)'!$A:$BQ,49,0) -> 0 | AW4: =VLOOKUP(A4,'Custo_Fopag (2)'!$A:$BQ,19,0) -> 0 | AX4: =VLOOKUP(A4,'Custo_Fopag (2)'!$A:$BQ,50,0) -> 0 | AY4: =VLOOKUP(A4,'Custo_Fopag (2)'!$A:$BQ,51,0) -> 0 | AZ4: 0 | BA4: =VLOOKUP(A4,'Custo_Fopag (2)'!$A:$BQ,54,0) -> 0 | BB4: =VLOOKUP(A4,'Custo_Fopag (2)'!$A:$BQ,52,0) -> 0 | BC4: =SUM(AH4:BB4) -> 512.87 | BD4: =BC4+AG4 -> 5081.62 | BF4: =BD4+BE4 -> 5081.62 | BG4: =AG4/12 -> 380.72917 | BH4: =BG4 -> 380.72917 | BI4: =BH4/3 -> 126.90972 | BJ4: =SUM(BG4:BI4) -> 888.36806 | BK4: =VLOOKUP(A4,'Custo_Fopag (2)'!$A:$BQ,65,0) -> 913.75 | BL4: =VLOOKUP(A4,'Custo_Fopag (2)'!$A:$BQP,66,0) -> 137.06 | BM4: =VLOOKUP(A4,'Custo_Fopag (2)'!$A:$BQ,67,0) -> 264.98 | BN4: =VLOOKUP(A4,'Custo_Fopag (2)'!$A:$BQ,64,0) -> 365.5 | BO4: =SUM(BK4:BN4) -> 1681.29 | BP4: =BF4+BO4 -> 6762.91 | BQ4: =BF4+BJ4+BO4 -> 7651.2781 | BR4: =VLOOKUP(A4,'Custo_Fopag (2)'!$A:$BQ,60,0) -> 0 | BS4: =IF(ISBLANK(L4),"Ativo","Desligado") -> Ativo
A5: ALEKSANDER APARECIDO GONÇALVES DA SILVA | B5: 46082 | C5: CLT | D5: =VLOOKUP(A5,'Custo_Fopag (2)'!A:$BQ,4,0) -> G3S FL 11 - MARINGA | G5: =VLOOKUP(A5,'Custo_Fopag (2)'!$A:$BQ,5,0) -> 20.947.332/0011-67 | H5: =VLOOKUP(A5,'Custo_Fopag (2)'!$A:$BQ,6,0) -> OPERACIONAL | I5: =VLOOKUP(A5,'Custo_Fopag (2)'!$A:$BQ,7,0) -> PATIO | J5: =VLOOKUP(A5,'Custo_Fopag (2)'!$A:$BQ,8,0) -> SELETIVA MARINGA CIDADE ALTA | K5: =VLOOKUP(A5,'Custo_Fopag (2)'!$A:$BQ,9,0) -> 46050 | L5: =VLOOKUP(A5,'Custo_Fopag (2)'!$A:$BQ,10,0) -> 46097 | N5: =VLOOKUP(A5,'Custo_Fopag (2)'!$A:$BQ,11,0) -> 1.2.8.3. OPERACIONAL | O5: =VLOOKUP(A5,'Custo_Fopag (2)'!$A:$BQ,12,0) -> GERENTE DE PATIO SENIOR | P5: =VLOOKUP(A5,'Custo_Fopag (2)'!$A:$BQ,13,0) -> 3679.83 | Q5: =VLOOKUP(A5,'Custo_Fopag (2)'!$A:$BQ,16,0) -> 0 | R5: =VLOOKUP(A5,'Custo_Fopag (2)'!$A:$BQ,17,0) -> 0 | S5: =VLOOKUP(A5,'Custo_Fopag (2)'!$A:$BP,18,0) -> 0 | T5: =VLOOKUP(A5,'Custo_Fopag (2)'!$A:$BQ,20,0) -> 392.52 | U5: =VLOOKUP(A5,'Custo_Fopag (2)'!$A:$BQ,21,0) -> 0 | V5: =VLOOKUP(A5,'Custo_Fopag (2)'!$A:$BQ,22,0) -> 588.77 | W5: =VLOOKUP(A5,'Custo_Fopag (2)'!$A:$BQ,23,0) -> 0 | X5: =VLOOKUP(A5,'Custo_Fopag (2)'!$A:$BQ,24,0) -> 0 | Y5: =VLOOKUP(A5,'Custo_Fopag (2)'!$A:$BQ,25,0) -> 0 | Z5: =VLOOKUP(A5,'Custo_Fopag (2)'!$A:$BQ,26,0) -> 0 | AA5: =VLOOKUP(A5,'Custo_Fopag (2)'!$A:$BQ,27,0) -> 0 | AB5: =VLOOKUP(A5,'Custo_Fopag (2)'!$A:$BQ,28,0) -> 47.77 | AC5: =VLOOKUP(A5,'Custo_Fopag (2)'!$A:$BQ,29,0) -> 0 | AD5: =VLOOKUP(A5,'Custo_Fopag (2)'!$A:$BQ,30,0) -> 0 | AE5: =VLOOKUP(A5,'Custo_Fopag (2)'!$A:$BQ,31,0) -> 0 | AF5: =VLOOKUP(A5,'Custo_Fopag (2)'!$A:$BQ,32,0) -> 0 | AG5: =SUM(Q5:AF5) -> 1029.06 | AH5: =VLOOKUP(A5,'Custo_Fopag (2)'!$A:$BQ,45,0) -> 0 | AI5: =_xlfn.XLOOKUP(A5,'Custo_Fopag (2)'!A:A,'Custo_Fopag (2)'!AT:AT,0,0,1) -> 266.67 | AJ5: =VLOOKUP(A5,'Custo_Fopag (2)'!$A:$BQ,47,0) -> 0 | AK5: 0 | AL5: =VLOOKUP(A5,'Custo_Fopag (2)'!$A:$BQ,35,0) -> 0 | AM5: =VLOOKUP(A5,'Custo_Fopag (2)'!$A:$BQ,36,0) -> 0 | AN5: =VLOOKUP(A5,'Custo_Fopag (2)'!$A:$BQ,37,0) -> 0 | AO5: =VLOOKUP(A5,'Custo_Fopag (2)'!$A:$BQ,39,0) -> 0 | AP5: =VLOOKUP(A5,'Custo_Fopag (2)'!$A:$BQ,42,0) -> 0 | AQ5: =VLOOKUP(A5,'Custo_Fopag (2)'!$A:$BQ,40,0) -> 0 | AR5: =VLOOKUP(A5,'Custo_Fopag (2)'!$A:$BQ,41,0) -> 28.92 | AS5: =VLOOKUP(A5,'Custo_Fopag (2)'!$A:$BQ,38,0) -> 0 | AT5: =VLOOKUP(A5,'Custo_Fopag (2)'!$A:$BQ,43,0) -> 0 | AU5: =VLOOKUP(A5,'Custo_Fopag (2)'!$A:$BQ,48,0) -> 0 | AV5: =VLOOKUP(A5,'Custo_Fopag (2)'!$A:$BQ,49,0) -> 0 | AW5: =VLOOKUP(A5,'Custo_Fopag (2)'!$A:$BQ,19,0) -> 0 | AX5: =VLOOKUP(A5,'Custo_Fopag (2)'!$A:$BQ,50,0) -> 0 | AY5: =VLOOKUP(A5,'Custo_Fopag (2)'!$A:$BQ,51,0) -> 0 | AZ5: 0 | BA5: =VLOOKUP(A5,'Custo_Fopag (2)'!$A:$BQ,54,0) -> 0 | BB5: =VLOOKUP(A5,'Custo_Fopag (2)'!$A:$BQ,52,0) -> 0 | BC5: =SUM(AH5:BB5) -> 295.59 | BD5: =BC5+AG5 -> 1324.65 | BF5: =BD5+BE5 -> 1324.65 | BG5: =AG5/12 -> 85.755 | BH5: =BG5 -> 85.755 | BI5: =BH5/3 -> 28.585 | BJ5: =SUM(BG5:BI5) -> 200.095 | BK5: =VLOOKUP(A5,'Custo_Fopag (2)'!$A:$BQ,65,0) -> 205.81 | BL5: =VLOOKUP(A5,'Custo_Fopag (2)'!$A:$BQP,66,0) -> 30.87 | BM5: =VLOOKUP(A5,'Custo_Fopag (2)'!$A:$BQ,67,0) -> 59.68 | BN5: =VLOOKUP(A5,'Custo_Fopag (2)'!$A:$BQ,64,0) -> 255.89 | BO5: =SUM(BK5:BN5) -> 552.25 | BP5: =BF5+BO5 -> 1876.9 | BQ5: =BF5+BJ5+BO5 -> 2076.995 | BR5: =VLOOKUP(A5,'Custo_Fopag (2)'!$A:$BQ,60,0) -> 4483.47 | BS5: =IF(ISBLANK(L5),"Ativo","Desligado") -> Desligado
A6: ALESSANDRA ARAUJO MOURA | B6: 46082 | C6: CLT | D6: =VLOOKUP(A6,'Custo_Fopag (2)'!A:$BQ,4,0) -> G3S FL 04 - PRES PRUD | G6: =VLOOKUP(A6,'Custo_Fopag (2)'!$A:$BQ,5,0) -> 20.947.332/0004-38 | H6: =VLOOKUP(A6,'Custo_Fopag (2)'!$A:$BQ,6,0) -> ADMINISTRATIVO | I6: =VLOOKUP(A6,'Custo_Fopag (2)'!$A:$BQ,7,0) -> ATENDIMENTO | J6: =VLOOKUP(A6,'Custo_Fopag (2)'!$A:$BQ,8,0) -> SELETIVA CORPORATIVO SUCATA | K6: =VLOOKUP(A6,'Custo_Fopag (2)'!$A:$BQ,9,0) -> 44783 | N6: =VLOOKUP(A6,'Custo_Fopag (2)'!$A:$BQ,11,0) -> 1.2.1.1 APOIO | O6: =VLOOKUP(A6,'Custo_Fopag (2)'!$A:$BQ,12,0) -> SUPERVISOR(A) ADMINISTRATIVO(A) | P6: =VLOOKUP(A6,'Custo_Fopag (2)'!$A:$BQ,13,0) -> 3392 | Q6: =VLOOKUP(A6,'Custo_Fopag (2)'!$A:$BQ,16,0) -> 3392 | R6: =VLOOKUP(A6,'Custo_Fopag (2)'!$A:$BQ,17,0) -> 0 | S6: =VLOOKUP(A6,'Custo_Fopag (2)'!$A:$BP,18,0) -> 0 | T6: =VLOOKUP(A6,'Custo_Fopag (2)'!$A:$BQ,20,0) -> 0 | U6: =VLOOKUP(A6,'Custo_Fopag (2)'!$A:$BQ,21,0) -> 0 | V6: =VLOOKUP(A6,'Custo_Fopag (2)'!$A:$BQ,22,0) -> 0 | W6: =VLOOKUP(A6,'Custo_Fopag (2)'!$A:$BQ,23,0) -> 1356.8 | X6: =VLOOKUP(A6,'Custo_Fopag (2)'!$A:$BQ,24,0) -> 0 | Y6: =VLOOKUP(A6,'Custo_Fopag (2)'!$A:$BQ,25,0) -> 0 | Z6: =VLOOKUP(A6,'Custo_Fopag (2)'!$A:$BQ,26,0) -> 0 | AA6: =VLOOKUP(A6,'Custo_Fopag (2)'!$A:$BQ,27,0) -> 0 | AB6: =VLOOKUP(A6,'Custo_Fopag (2)'!$A:$BQ,28,0) -> 0 | AC6: =VLOOKUP(A6,'Custo_Fopag (2)'!$A:$BQ,29,0) -> 0 | AD6: =VLOOKUP(A6,'Custo_Fopag (2)'!$A:$BQ,30,0) -> 0 | AE6: =VLOOKUP(A6,'Custo_Fopag (2)'!$A:$BQ,31,0) -> 0 | AF6: =VLOOKUP(A6,'Custo_Fopag (2)'!$A:$BQ,32,0) -> 0 | AG6: =SUM(Q6:AF6) -> 4748.8 | AH6: =VLOOKUP(A6,'Custo_Fopag (2)'!$A:$BQ,45,0) -> 0 | AI6: =_xlfn.XLOOKUP(A6,Beneficios!A:A,Beneficios!B:B,0,0,1) -> 521.87 | AJ6: =VLOOKUP(A6,'Custo_Fopag (2)'!$A:$BQ,47,0) -> 0 | AK6: 0 | AL6: =VLOOKUP(A6,'Custo_Fopag (2)'!$A:$BQ,35,0) -> 0 | AM6: =VLOOKUP(A6,'Custo_Fopag (2)'!$A:$BQ,36,0) -> 0 | AN6: =VLOOKUP(A6,'Custo_Fopag (2)'!$A:$BQ,37,0) -> 0 | AO6: =VLOOKUP(A6,'Custo_Fopag (2)'!$A:$BQ,39,0) -> 0 | AP6: =VLOOKUP(A6,'Custo_Fopag (2)'!$A:$BQ,42,0) -> 0 | AQ6: =VLOOKUP(A6,'Custo_Fopag (2)'!$A:$BQ,40,0) -> 0 | AR6: =VLOOKUP(A6,'Custo_Fopag (2)'!$A:$BQ,41,0) -> 904.34 | AS6: =VLOOKUP(A6,'Custo_Fopag (2)'!$A:$BQ,38,0) -> 0 | AT6: =VLOOKUP(A6,'Custo_Fopag (2)'!$A:$BQ,43,0) -> 0 | AU6: =VLOOKUP(A6,'Custo_Fopag (2)'!$A:$BQ,48,0) -> 0 | AV6: =VLOOKUP(A6,'Custo_Fopag (2)'!$A:$BQ,49,0) -> 0 | AW6: =VLOOKUP(A6,'Custo_Fopag (2)'!$A:$BQ,19,0) -> 0 | AX6: =VLOOKUP(A6,'Custo_Fopag (2)'!$A:$BQ,50,0) -> 0 | AY6: =VLOOKUP(A6,'Custo_Fopag (2)'!$A:$BQ,51,0) -> 0 | AZ6: 0 | BA6: =VLOOKUP(A6,'Custo_Fopag (2)'!$A:$BQ,54,0) -> 0 | BB6: =VLOOKUP(A6,'Custo_Fopag (2)'!$A:$BQ,52,0) -> 0 | BC6: =SUM(AH6:BB6) -> 1426.21 | BD6: =BC6+AG6 -> 6175.01 | BF6: =BD6+BE6 -> 6175.01 | BG6: =AG6/12 -> 395.73333 | BH6: =BG6 -> 395.73333 | BI6: =BH6/3 -> 131.91111 | BJ6: =SUM(BG6:BI6) -> 923.37778 | BK6: =VLOOKUP(A6,'Custo_Fopag (2)'!$A:$BQ,65,0) -> 949.76 | BL6: =VLOOKUP(A6,'Custo_Fopag (2)'!$A:$BQP,66,0) -> 71.23 | BM6: =VLOOKUP(A6,'Custo_Fopag (2)'!$A:$BQ,67,0) -> 275.43 | BN6: =VLOOKUP(A6,'Custo_Fopag (2)'!$A:$BQ,64,0) -> 379.9 | BO6: =SUM(BK6:BN6) -> 1676.32 | BP6: =BF6+BO6 -> 7851.33 | BQ6: =BF6+BJ6+BO6 -> 8774.7078 | BR6: =VLOOKUP(A6,'Custo_Fopag (2)'!$A:$BQ,60,0) -> 0 | BS6: =IF(ISBLANK(L6),"Ativo","Desligado") -> Ativo
A7: ALIFER BRENO PEREIRA ALMEIDA DE JESUS | B7: 46082 | C7: CLT | D7: =VLOOKUP(A7,'Custo_Fopag (2)'!A:$BQ,4,0) -> G3S FL 06 - MARINGA | G7: =VLOOKUP(A7,'Custo_Fopag (2)'!$A:$BQ,5,0) -> 20.947.332/0006-08 | H7: =VLOOKUP(A7,'Custo_Fopag (2)'!$A:$BQ,6,0) -> ADMINISTRATIVO | I7: =VLOOKUP(A7,'Custo_Fopag (2)'!$A:$BQ,7,0) -> ATENDIMENTO | J7: =VLOOKUP(A7,'Custo_Fopag (2)'!$A:$BQ,8,0) -> SELETIVA MARINGA DISTRITO | K7: =VLOOKUP(A7,'Custo_Fopag (2)'!$A:$BQ,9,0) -> 46034 | N7: =VLOOKUP(A7,'Custo_Fopag (2)'!$A:$BQ,11,0) -> 1.2.4.1 ADMINISTRATIVO | O7: =VLOOKUP(A7,'Custo_Fopag (2)'!$A:$BQ,12,0) -> AUX ADMINISTRATIVO JUNIOR | P7: =VLOOKUP(A7,'Custo_Fopag (2)'!$A:$BQ,13,0) -> 2320 | Q7: =VLOOKUP(A7,'Custo_Fopag (2)'!$A:$BQ,16,0) -> 2320 | R7: =VLOOKUP(A7,'Custo_Fopag (2)'!$A:$BQ,17,0) -> 0 | S7: =VLOOKUP(A7,'Custo_Fopag (2)'!$A:$BP,18,0) -> 0 | T7: =VLOOKUP(A7,'Custo_Fopag (2)'!$A:$BQ,20,0) -> 0 | U7: =VLOOKUP(A7,'Custo_Fopag (2)'!$A:$BQ,21,0) -> 0 | V7: =VLOOKUP(A7,'Custo_Fopag (2)'!$A:$BQ,22,0) -> 0 | W7: =VLOOKUP(A7,'Custo_Fopag (2)'!$A:$BQ,23,0) -> 0 | X7: =VLOOKUP(A7,'Custo_Fopag (2)'!$A:$BQ,24,0) -> 0 | Y7: =VLOOKUP(A7,'Custo_Fopag (2)'!$A:$BQ,25,0) -> 0 | Z7: =VLOOKUP(A7,'Custo_Fopag (2)'!$A:$BQ,26,0) -> 0 | AA7: =VLOOKUP(A7,'Custo_Fopag (2)'!$A:$BQ,27,0) -> 236.35 | AB7: =VLOOKUP(A7,'Custo_Fopag (2)'!$A:$BQ,28,0) -> 66.81 | AC7: =VLOOKUP(A7,'Custo_Fopag (2)'!$A:$BQ,29,0) -> 0 | AD7: =VLOOKUP(A7,'Custo_Fopag (2)'!$A:$BQ,30,0) -> 0 | AE7: =VLOOKUP(A7,'Custo_Fopag (2)'!$A:$BQ,31,0) -> 0 | AF7: =VLOOKUP(A7,'Custo_Fopag (2)'!$A:$BQ,32,0) -> 0 | AG7: =SUM(Q7:AF7) -> 2623.16 | AH7: =VLOOKUP(A7,'Custo_Fopag (2)'!$A:$BQ,45,0) -> 0 | AI7: =_xlfn.XLOOKUP(A7,Beneficios!A:A,Beneficios!B:B,0,0,1) -> 0 | AJ7: =VLOOKUP(A7,'Custo_Fopag (2)'!$A:$BQ,47,0) -> 0 | AK7: 0 | AL7: =VLOOKUP(A7,'Custo_Fopag (2)'!$A:$BQ,35,0) -> 0 | AM7: =VLOOKUP(A7,'Custo_Fopag (2)'!$A:$BQ,36,0) -> 0 | AN7: =VLOOKUP(A7,'Custo_Fopag (2)'!$A:$BQ,37,0) -> 0 | AO7: =VLOOKUP(A7,'Custo_Fopag (2)'!$A:$BQ,39,0) -> 0 | AP7: =VLOOKUP(A7,'Custo_Fopag (2)'!$A:$BQ,42,0) -> 0 | AQ7: =VLOOKUP(A7,'Custo_Fopag (2)'!$A:$BQ,40,0) -> 0 | AR7: =VLOOKUP(A7,'Custo_Fopag (2)'!$A:$BQ,41,0) -> 456.6 | AS7: =VLOOKUP(A7,'Custo_Fopag (2)'!$A:$BQ,38,0) -> 0 | AT7: =VLOOKUP(A7,'Custo_Fopag (2)'!$A:$BQ,43,0) -> 0 | AU7: =VLOOKUP(A7,'Custo_Fopag (2)'!$A:$BQ,48,0) -> 0 | AV7: =VLOOKUP(A7,'Custo_Fopag (2)'!$A:$BQ,49,0) -> 0 | AW7: =VLOOKUP(A7,'Custo_Fopag (2)'!$A:$BQ,19,0) -> 0 | AX7: =VLOOKUP(A7,'Custo_Fopag (2)'!$A:$BQ,50,0) -> 0 | AY7: =VLOOKUP(A7,'Custo_Fopag (2)'!$A:$BQ,51,0) -> 0 | AZ7: 0 | BA7: =VLOOKUP(A7,'Custo_Fopag (2)'!$A:$BQ,54,0) -> 0 | BB7: =VLOOKUP(A7,'Custo_Fopag (2)'!$A:$BQ,52,0) -> 0 | BC7: =SUM(AH7:BB7) -> 456.6 | BD7: =BC7+AG7 -> 3079.76 | BF7: =BD7+BE7 -> 3079.76 | BG7: =AG7/12 -> 218.59667 | BH7: =BG7 -> 218.59667 | BI7: =BH7/3 -> 72.865556 | BJ7: =SUM(BG7:BI7) -> 510.05889 | BK7: =VLOOKUP(A7,'Custo_Fopag (2)'!$A:$BQ,65,0) -> 524.63 | BL7: =VLOOKUP(A7,'Custo_Fopag (2)'!$A:$BQP,66,0) -> 39.34 | BM7: =VLOOKUP(A7,'Custo_Fopag (2)'!$A:$BQ,67,0) -> 152.14 | BN7: =VLOOKUP(A7,'Custo_Fopag (2)'!$A:$BQ,64,0) -> 218.4 | BO7: =SUM(BK7:BN7) -> 934.51 | BP7: =BF7+BO7 -> 4014.27 | BQ7: =BF7+BJ7+BO7 -> 4524.3289 | BR7: =VLOOKUP(A7,'Custo_Fopag (2)'!$A:$BQ,60,0) -> 0 | BS7: =IF(ISBLANK(L7),"Ativo","Desligado") -> Ativo
