Workbook

Sheet Atividades
A1: DATA | B1: EMPRESA | C1: RESUMO ATIV. | D1: DESCRIÇÃO DA ATIV. | E1: INICIAL | F1: FINAL | G1: QTDE DE HORAS
A2: 23/05/2026 | B2: G3S 10 | C2: BCBI Seletiva | D2: Operação assistida do sistema de BI da seletiva, acompanhamento e checagem de erros no sistema | E2: 0.32291667 | F2: 0.41666667 | G2: 0.09375
A3: 20/05/2026 | B3: G3S 10 | C3: BCBI Seletiva | D3: Operação assistida do sistema de BI da seletiva, acompanhamento e checagem de erros no sistema | E3: 0.32430556 | F3: 0.4375 | G3: 0.11319444
A4: 21/05/2026 | B4: G3S 10 | C4: BCBI Seletiva | D4: Operação assistida do sistema de BI da seletiva, acompanhamento e checagem de erros no sistema | E4: 0.32430556 | F4: 0.35416667 | G4: 0.029861111
A5: 14/05/2026 | B5: G3S 10 | C5: BCBI Seletiva | D5: Operação assistida do sistema de BI da seletiva | E5: 0.32638889 | F5: 0.35416667 | G5: 0.027777778
A6: 22/05/2026 | B6: G3S 10 | C6: BCBI Seletiva | D6: Atualização do ODBC e verificação de integridade dos dados | E6: 0.32708333 | F6: 0.4375 | G6: 0.11041667
A7: 15/05/2026 | B7: G3S 10 | C7: BCBI Seletiva | D7: Operação assistida do sistema de BI da seletiva, acompanhamento e checagem de erros no sistema | E7: 0.32777778 | F7: 0.4375 | G7: 0.10972222
A8: 24/05/2026 | B8: G3S 10 | C8: Fechamento | D8: Tratamento dos dados de fechamento abril pré carga | E8: 0.32777778 | F8: 0.41666667 | G8: 0.088888889
A9: 16/05/2026 | B9: G3S 10 | C9: Fechamento | D9: Tratamento dos dados de fechamento abril pré carga | E9: 0.32916667 | F9: 0.41666667 | G9: 0.0875
A10: 26/05/2026 | B10: G3S 10 | C10: BCBI Seletiva | D10: Auditoria entre relatórios do SAGI e dados do BCBI | E10: 0.32986111 | F10: 0.41666667 | G10: 0.086805556
A11: 27/05/2026 | B11: G3S 10 | C11: BCBI Seletiva | D11: Operação assistida do sistema de BI da seletiva, acompanhamento e checagem de erros no sistema | E11: 0.32986111 | F11: 0.41666667 | G11: 0.086805556
A12: 19/05/2026 | B12: G3S 10 | C12: BCBI Seletiva | D12: Auditoria entre relatórios do SAGI e dados do BCBI | E12: 0.33194444 | F12: 0.4375 | G12: 0.10555556
A13: 13/04/2026 | B13: G3S 10 | C13: BCBI Seletiva | D13: Operação assistida do sistema de BI da seletiva, acompanhamento e checagem de erros no sistema | E13: 0.33333333 | F13: 0.4375 | G13: 0.10416667
... A88: 27/04/2026 | B88: G3S 10 | C88: Fechamento | D88: Finalização e validação dos dados de fechamento | E88: 0.66666667 | F88: 0.75 | G88: 0.083333333
A89: 45992 | B89: G3S | C89: Suporte Áreas | D89: relatório Horas extras marcondes 24-25 | E89: 0.5 | F89: 0.65277778 | G89: 0.15277778
A90: 45992 | B90: EKIPA | C90: Centro de custo | D90: Adequação de centro de custo da máquina phh0044(atual gbl8h44) | E90: 0.65277778 | F90: 0.67708333 | G90: 0.024305556
A91: 45992 | B91: G3S 10 | C91: Fechamento | D91: Tratamento dos dados de fechamento pré carga | E91: 0.67708333 | F91: 0.75 | G91: 0.072916667
A92: 45993 | B92: G3S 10 | C92: Fechamento | D92: Tratamento dos dados de fechamento pré carga | E92: 0.5 | F92: 0.625 | G92: 0.125
A93: 45993 | B93: G3S 10 | C93: Suporte Áreas | D93: Criação arquivo "cola" de rateio de centro de custo estagiários para a Elaine do RH | E93: 0.625 | F93: 0.63888889 | G93: 0.013888889
A94: 45993 | B94: G3S 10 | C94: Fechamento | D94: Tratamento dos dados de fechamento pré carga | E94: 0.63888889 | F94: 0.75 | G94: 0.11111111
A95: 45994 | B95: G3S 10 | C95: Fechamento | D95: Tratamento dos dados de fechamento pré carga | E95: 0.33333333 | F95: 0.375 | G95: 0.041666667
A96: 45994 | B96: G3S 10 | C96: Sagi | D96: Abertura de chamado no SAGI para solução de troca do tipo de centro de custo, mas não foi resolvido, iremos acionar o Leonardo | E96: 0.375 | F96: 0.40763889 | G96: 0.032638889
A97: 45994 | B97: G3S 10 | C97: Fechamento | D97: Tratamento dos dados de fechamento pré carga | E97: 0.40763889 | F97: 0.48958333 | G97: 0.081944444
A98: 45994 | B98: G3S 10 | C98: Fechamento | D98: Tratamento dos dados de fechamento pré carga | E98: 0.53125 | F98: 0.58333333 | G98: 0.052083333
A99: 45994 | B99: G3S 10 | C99: Suporte Áreas | D99: Cálculo/definição dos rateios a serem feitos para cada empresa | E99: 0.58333333 | F99: 0.625 | G99: 0.041666667
A100: 45995 | B100: G3S | C100: BCBI Seletiva | D100: Operação assistida do sistema de BI da seletiva, acompanhamento e checagem de erros no sistema | E100: 0.33333333 | F100: 0.36111111 | G100: 0.027777778
... A355: 46098 | B355: G3S 10 | C355: BCBI Seletiva | D355: Checagens BCBI solicitadas por Luciano | E355: 0.59375 | F355: 0.625 | G355: 0.03125
A356: 46099 | B356: G3S 10 | C356: LEONARDO | D356: Translado leonardo Comfort X Seletiva' | E356: - | F356: - | G356: -
A357: 46099 | B357: G3S 10 | C357: Fechamento | D357: Correção de lançamentos SAGI | E357: 0.33333333 | F357: 0.375 | G357: 0.041666667
A358: 46099 | B358: G3S 10 | C358: Rh | D358: treinamento estagiários | E358: 0.375 | F358: 0.4375 | G358: 0.0625
A359: 46099 | B359: G&S | C359: Suporte Áreas | D359: Geração de relatório de custos ekipa intralogística e ECO EXPO | E359: 0.4375 | F359: 0.45833333 | G359: 0.020833333
A360: 46099 | B360: G3S 10 | C360: Fechamento | D360: fechamento dados abastecimentos | E360: 0.45833333 | F360: 0.51736111 | G360: 0.059027778
A361: 46099 | B361: G3S 10 | C361: Fechamento | D361: fechamento dados abastecimentos | E361: 0.55902778 | F361: 0.625 | G361: 0.065972222
A362: 46100 | B362: G3S 10 | C362: Qualidade | D362: Overview Pedro X Julio | E362: 0.33333333 | F362: 0.51041667 | G362: 0.17708333
A363: 46100 | B363: G3S 10 | C363: Qualidade | D363: Overview Pedro X Julio | E363: 0.55208333 | F363: 0.625 | G363: 0.072916667
A364: 46101 | B364: G3S 10 | C364: Qualidade | D364: Overview Pedro X Julio | E364: 0.33333333 | F364: 0.35416667 | G364: 0.020833333
A365: 46101 | B365: G3S 10 | C365: BCBI Seletiva | D365: Reunião Leonardo, Luciano, Júlio, Caíque, Matheus para alinharmos integração FOPA x BCBI | E365: 0.35416667 | F365: 0.375 | G365: 0.020833333
A366: 46101 | B366: G3S 10 | C366: Qualidade | D366: Overview Pedro X Julio | E366: 0.375 | F366: 0.51736111 | G366: 0.14236111
A367: 46101 | B367: G3S 10 | C367: Qualidade | D367: Overview Pedro X Julio | E367: 0.55902778 | F367: 0.625 | G367: 0.065972222
A368: 46104 | B368: G3S 10 | C368: Qualidade | D368: Cadastro nos sistemas | E368: 0.33333333 | F368: 0.5 | G368: 0.16666667
...

Sheet Banco de Horas
A1: DATA | B1: HORA INICIAL | C1: HORA FINAL | D1: HORAS TRABALHADAS | E1: HORAS ESPERADAS | F1: BANCO DO DIA | G1: COMPENSAÇÃO | H1: BANCO FINAL | I1: BANCO ACUMULADO
A2: 45992 | B2: =_xlfn.MINIFS(Atividades!$E:$E,Atividades!$A:$A, A2) | C2: =_xlfn.MAXIFS(Atividades!$F:$F, Atividades!$A:$A, A2) | D2: =IF(C2-B2>TIME(6,0,0), (C2-B2)-TIME(1,0,0), C2-B2) | E2: =IF(OR(D2<=0, B2="", C2=""), 0, TIME(6,0,0)) | F2: =D2-E2 | G2: 0 | H2: =F2-G2 | I2: =H2
A3: 45993 | B3: =_xlfn.MINIFS(Atividades!$E:$E,Atividades!$A:$A, A3) | C3: =_xlfn.MAXIFS(Atividades!$F:$F, Atividades!$A:$A, A3) | D3: =IF(C3-B3>TIME(6,0,0), (C3-B3)-TIME(1,0,0), C3-B3) | E3: =IF(OR(D3<=0, B3="", C3=""), 0, TIME(6,0,0)) | F3: =D3-E3 | G3: 0 | H3: =F3-G3 | I3: =I2+H3
A4: 45994 | B4: =_xlfn.MINIFS(Atividades!$E:$E,Atividades!$A:$A, A4) | C4: =_xlfn.MAXIFS(Atividades!$F:$F, Atividades!$A:$A, A4) | D4: =IF(C4-B4>TIME(6,0,0), (C4-B4)-TIME(1,0,0), C4-B4) | E4: =IF(OR(D4<=0, B4="", C4=""), 0, TIME(6,0,0)) | F4: =D4-E4 | G4: 0 | H4: =F4-G4 | I4: =I3+H4
A5: 45995 | B5: =_xlfn.MINIFS(Atividades!$E:$E,Atividades!$A:$A, A5) | C5: =_xlfn.MAXIFS(Atividades!$F:$F, Atividades!$A:$A, A5) | D5: =IF(C5-B5>TIME(6,0,0), (C5-B5)-TIME(1,0,0), C5-B5) | E5: =IF(OR(D5<=0, B5="", C5=""), 0, TIME(6,0,0)) | F5: =D5-E5 | G5: 0 | H5: =F5-G5 | I5: =I4+H5
A6: 45996 | B6: =_xlfn.MINIFS(Atividades!$E:$E,Atividades!$A:$A, A6) | C6: =_xlfn.MAXIFS(Atividades!$F:$F, Atividades!$A:$A, A6) | D6: =IF(C6-B6>TIME(6,0,0), (C6-B6)-TIME(1,0,0), C6-B6) | E6: =IF(OR(D6<=0, B6="", C6=""), 0, TIME(6,0,0)) | F6: =D6-E6 | G6: 0 | H6: =F6-G6 | I6: =I5+H6
A7: 45999 | B7: =_xlfn.MINIFS(Atividades!$E:$E,Atividades!$A:$A, A7) | C7: =_xlfn.MAXIFS(Atividades!$F:$F, Atividades!$A:$A, A7) | D7: =IF(C7-B7>TIME(6,0,0), (C7-B7)-TIME(1,0,0), C7-B7) | E7: =IF(OR(D7<=0, B7="", C7=""), 0, TIME(6,0,0)) | F7: =D7-E7 | G7: 0 | H7: =F7-G7 | I7: =I6+H7
A8: 46000 | B8: =_xlfn.MINIFS(Atividades!$E:$E,Atividades!$A:$A, A8) | C8: 0.62847222 | D8: =IF(C8-B8>TIME(6,0,0), (C8-B8)-TIME(1,0,0), C8-B8) | E8: =IF(OR(D8<=0, B8="", C8=""), 0, TIME(6,0,0)) | F8: =D8-E8 | G8: 0 | H8: =F8-G8 | I8: =I7+H8
A9: 46001 | B9: =_xlfn.MINIFS(Atividades!$E:$E,Atividades!$A:$A, A9) | C9: =_xlfn.MAXIFS(Atividades!$F:$F, Atividades!$A:$A, A9) | D9: =IF(C9-B9>TIME(6,0,0), (C9-B9)-TIME(1,0,0), C9-B9) | E9: =IF(OR(D9<=0, B9="", C9=""), 0, TIME(6,0,0)) | F9: =D9-E9 | G9: 0 | H9: =F9-G9 | I9: =I8+H9
A10: 46002 | B10: =_xlfn.MINIFS(Atividades!$E:$E,Atividades!$A:$A, A10) | C10: =_xlfn.MAXIFS(Atividades!$F:$F, Atividades!$A:$A, A10) | D10: =IF(C10-B10>TIME(6,0,0), (C10-B10)-TIME(1,0,0), C10-B10) | E10: =IF(OR(D10<=0, B10="", C10=""), 0, TIME(6,0,0)) | F10: =D10-E10 | G10: 0 | H10: =F10-G10 | I10: =I9+H10
A11: 46003 | B11: =_xlfn.MINIFS(Atividades!$E:$E,Atividades!$A:$A, A11) | C11: =_xlfn.MAXIFS(Atividades!$F:$F, Atividades!$A:$A, A11) | D11: =IF(C11-B11>TIME(6,0,0), (C11-B11)-TIME(1,0,0), C11-B11) | E11: =IF(OR(D11<=0, B11="", C11=""), 0, TIME(6,0,0)) | F11: =D11-E11 | G11: 0 | H11: =F11-G11 | I11: =I10+H11
A12: 46006 | B12: =_xlfn.MINIFS(Atividades!$E:$E,Atividades!$A:$A, A12) | C12: =_xlfn.MAXIFS(Atividades!$F:$F, Atividades!$A:$A, A12) | D12: =IF(C12-B12>TIME(6,0,0), (C12-B12)-TIME(1,0,0), C12-B12) | E12: =IF(OR(D12<=0, B12="", C12=""), 0, TIME(6,0,0)) | F12: =D12-E12 | G12: 0 | H12: =F12-G12 | I12: =I11+H12
A13: 46007 | B13: =_xlfn.MINIFS(Atividades!$E:$E,Atividades!$A:$A, A13) | C13: =_xlfn.MAXIFS(Atividades!$F:$F, Atividades!$A:$A, A13) | D13: =IF(C13-B13>TIME(6,0,0), (C13-B13)-TIME(1,0,0), C13-B13) | E13: =IF(OR(D13<=0, B13="", C13=""), 0, TIME(6,0,0)) | F13: =D13-E13 | G13: 0 | H13: =F13-G13 | I13: =I12+H13
A14: 46008 | B14: =_xlfn.MINIFS(Atividades!$E:$E,Atividades!$A:$A, A14) | C14: =_xlfn.MAXIFS(Atividades!$F:$F, Atividades!$A:$A, A14) | D14: =IF(C14-B14>TIME(6,0,0), (C14-B14)-TIME(1,0,0), C14-B14) | E14: =IF(OR(D14<=0, B14="", C14=""), 0, TIME(6,0,0)) | F14: =D14-E14 | G14: 0 | H14: =F14-G14 | I14: =I13+H14
A15: 46027 | B15: =_xlfn.MINIFS(Atividades!$E:$E,Atividades!$A:$A, A15) | C15: 0.62986111 | D15: 0.26388889 | E15: =IF(OR(D15<=0, B15="", C15=""), 0, TIME(6,0,0)) | F15: =D15-E15 | G15: 0 | H15: =F15-G15 | I15: =I14+H15
A16: 46028 | B16: =_xlfn.MINIFS(Atividades!$E:$E,Atividades!$A:$A, A16) | C16: =_xlfn.MAXIFS(Atividades!$F:$F, Atividades!$A:$A, A16) | D16: =IF(C16-B16>TIME(6,0,0), (C16-B16)-TIME(1,0,0), C16-B16) | E16: =IF(OR(D16<=0, B16="", C16=""), 0, TIME(6,0,0)) | F16: =D16-E16 | G16: 0 | H16: =F16-G16 | I16: =I15+H16
A17: 46029 | B17: =_xlfn.MINIFS(Atividades!$E:$E,Atividades!$A:$A, A17) | C17: =_xlfn.MAXIFS(Atividades!$F:$F, Atividades!$A:$A, A17) | D17: =IF(C17-B17>TIME(6,0,0), (C17-B17)-TIME(1,0,0), C17-B17) | E17: =IF(OR(D17<=0, B17="", C17=""), 0, TIME(6,0,0)) | F17: =D17-E17 | G17: 0 | H17: =F17-G17 | I17: =I16+H17
A18: 46030 | B18: =_xlfn.MINIFS(Atividades!$E:$E,Atividades!$A:$A, A18) | C18: =_xlfn.MAXIFS(Atividades!$F:$F, Atividades!$A:$A, A18) | D18: =IF(C18-B18>TIME(6,0,0), (C18-B18)-TIME(1,0,0), C18-B18) | E18: =IF(OR(D18<=0, B18="", C18=""), 0, TIME(6,0,0)) | F18: =D18-E18 | G18: 0 | H18: =F18-G18 | I18: =I17+H18
A19: 46031 | B19: =_xlfn.MINIFS(Atividades!$E:$E,Atividades!$A:$A, A19) | C19: =_xlfn.MAXIFS(Atividades!$F:$F, Atividades!$A:$A, A19) | D19: =IF(C19-B19>TIME(6,0,0), (C19-B19)-TIME(1,0,0), C19-B19) | E19: =IF(OR(D19<=0, B19="", C19=""), 0, TIME(6,0,0)) | F19: =D19-E19 | G19: 0 | H19: =F19-G19 | I19: =I18+H19
A20: 46034 | B20: =_xlfn.MINIFS(Atividades!$E:$E,Atividades!$A:$A, A20) | C20: =_xlfn.MAXIFS(Atividades!$F:$F, Atividades!$A:$A, A20) | D20: =IF(C20-B20>TIME(6,0,0), (C20-B20)-TIME(1,0,0), C20-B20) | E20: =IF(OR(D20<=0, B20="", C20=""), 0, TIME(6,0,0)) | F20: =D20-E20 | G20: 0 | H20: =F20-G20 | I20: =I19+H20
A21: 46035 | B21: =_xlfn.MINIFS(Atividades!$E:$E,Atividades!$A:$A, A21) | C21: =_xlfn.MAXIFS(Atividades!$F:$F, Atividades!$A:$A, A21) | D21: =IF(C21-B21>TIME(6,0,0), (C21-B21)-TIME(1,0,0), C21-B21) | E21: =IF(OR(D21<=0, B21="", C21=""), 0, TIME(6,0,0)) | F21: =D21-E21 | G21: 0 | H21: =F21-G21 | I21: =I20+H21
A22: 46036 | B22: =_xlfn.MINIFS(Atividades!$E:$E,Atividades!$A:$A, A22) | C22: =_xlfn.MAXIFS(Atividades!$F:$F, Atividades!$A:$A, A22) | D22: =IF(C22-B22>TIME(6,0,0), (C22-B22)-TIME(1,0,0), C22-B22) | E22: =IF(OR(D22<=0, B22="", C22=""), 0, TIME(6,0,0)) | F22: =D22-E22 | G22: 0 | H22: =F22-G22 | I22: =I21+H22
A23: 46037 | B23: =_xlfn.MINIFS(Atividades!$E:$E,Atividades!$A:$A, A23) | C23: =_xlfn.MAXIFS(Atividades!$F:$F, Atividades!$A:$A, A23) | D23: =IF(C23-B23>TIME(6,0,0), (C23-B23)-TIME(1,0,0), C23-B23) | E23: =IF(OR(D23<=0, B23="", C23=""), 0, TIME(6,0,0)) | F23: =D23-E23 | G23: 0 | H23: =F23-G23 | I23: =I22+H23
A24: 46038 | B24: =_xlfn.MINIFS(Atividades!$E:$E,Atividades!$A:$A, A24) | C24: =_xlfn.MAXIFS(Atividades!$F:$F, Atividades!$A:$A, A24) | D24: =IF(C24-B24>TIME(6,0,0), (C24-B24)-TIME(1,0,0), C24-B24) | E24: =IF(OR(D24<=0, B24="", C24=""), 0, TIME(6,0,0)) | F24: =D24-E24 | G24: 0 | H24: =F24-G24 | I24: =I23+H24
A25: 46041 | B25: =_xlfn.MINIFS(Atividades!$E:$E,Atividades!$A:$A, A25) | C25: =_xlfn.MAXIFS(Atividades!$F:$F, Atividades!$A:$A, A25) | D25: =IF(C25-B25>TIME(6,0,0), (C25-B25)-TIME(1,0,0), C25-B25) | E25: =IF(OR(D25<=0, B25="", C25=""), 0, TIME(6,0,0)) | F25: =D25-E25 | G25: 0 | H25: =F25-G25 | I25: =I24+H25
A26: 46043 | B26: =_xlfn.MINIFS(Atividades!$E:$E,Atividades!$A:$A, A26) | C26: =_xlfn.MAXIFS(Atividades!$F:$F, Atividades!$A:$A, A26) | D26: =IF(C26-B26>TIME(6,0,0), (C26-B26)-TIME(1,0,0), C26-B26) | E26: =IF(OR(D26<=0, B26="", C26=""), 0, TIME(6,0,0)) | F26: =D26-E26 | G26: 0 | H26: =F26-G26 | I26: =I25+H26
A27: 46044 | B27: =_xlfn.MINIFS(Atividades!$E:$E,Atividades!$A:$A, A27) | C27: =_xlfn.MAXIFS(Atividades!$F:$F, Atividades!$A:$A, A27) | D27: =IF(C27-B27>TIME(6,0,0), (C27-B27)-TIME(1,0,0), C27-B27) | E27: =IF(OR(D27<=0, B27="", C27=""), 0, TIME(6,0,0)) | F27: =D27-E27 | G27: 0 | H27: =F27-G27 | I27: =I26+H27
A28: 46045 | B28: =_xlfn.MINIFS(Atividades!$E:$E,Atividades!$A:$A, A28) | C28: =_xlfn.MAXIFS(Atividades!$F:$F, Atividades!$A:$A, A28) | D28: =IF(C28-B28>TIME(6,0,0), (C28-B28)-TIME(1,0,0), C28-B28) | E28: =IF(OR(D28<=0, B28="", C28=""), 0, TIME(6,0,0)) | F28: 0 | G28: 0.083333333 | H28: =F28-G28 | I28: =I27+H28
A29: 46048 | B29: =_xlfn.MINIFS(Atividades!$E:$E,Atividades!$A:$A, A29) | C29: =_xlfn.MAXIFS(Atividades!$F:$F, Atividades!$A:$A, A29) | D29: =IF(C29-B29>TIME(6,0,0), (C29-B29)-TIME(1,0,0), C29-B29) | E29: =IF(OR(D29<=0, B29="", C29=""), 0, TIME(6,0,0)) | F29: =D29-E29 | G29: 0 | H29: =F29-G29 | I29: =I28+H29
A30: 46049 | B30: =_xlfn.MINIFS(Atividades!$E:$E,Atividades!$A:$A, A30) | C30: =_xlfn.MAXIFS(Atividades!$F:$F, Atividades!$A:$A, A30) | D30: =IF(C30-B30>TIME(6,0,0), (C30-B30)-TIME(1,0,0), C30-B30) | E30: =IF(OR(D30<=0, B30="", C30=""), 0, TIME(6,0,0)) | F30: =D30-E30 | G30: 0 | H30: =F30-G30 | I30: =I29+H30
A31: 46050 | B31: =_xlfn.MINIFS(Atividades!$E:$E,Atividades!$A:$A, A31) | C31: =_xlfn.MAXIFS(Atividades!$F:$F, Atividades!$A:$A, A31) | D31: =IF(C31-B31>TIME(6,0,0), (C31-B31)-TIME(1,0,0), C31-B31) | E31: =IF(OR(D31<=0, B31="", C31=""), 0, TIME(6,0,0)) | F31: =D31-E31 | G31: 0 | H31: =F31-G31 | I31: =I30+H31
A32: 46051 | B32: =_xlfn.MINIFS(Atividades!$E:$E,Atividades!$A:$A, A32) | C32: =_xlfn.MAXIFS(Atividades!$F:$F, Atividades!$A:$A, A32) | D32: =IF(C32-B32>TIME(6,0,0), (C32-B32)-TIME(1,0,0), C32-B32) | E32: =IF(OR(D32<=0, B32="", C32=""), 0, TIME(6,0,0)) | F32: =D32-E32 | G32: 0 | H32: =F32-G32 | I32: =I31+H32
A33: 46052 | B33: =_xlfn.MINIFS(Atividades!$E:$E,Atividades!$A:$A, A33) | C33: =_xlfn.MAXIFS(Atividades!$F:$F, Atividades!$A:$A, A33) | D33: =IF(C33-B33>TIME(6,0,0), (C33-B33)-TIME(1,0,0), C33-B33) | E33: =IF(OR(D33<=0, B33="", C33=""), 0, TIME(6,0,0)) | F33: =D33-E33 | G33: 0 | H33: =F33-G33 | I33: =I32+H33
A34: 46055 | B34: =_xlfn.MINIFS(Atividades!$E:$E,Atividades!$A:$A, A34) | C34: =_xlfn.MAXIFS(Atividades!$F:$F, Atividades!$A:$A, A34) | D34: =IF(C34-B34>TIME(6,0,0), (C34-B34)-TIME(1,0,0), C34-B34) | E34: =IF(OR(D34<=0, B34="", C34=""), 0, TIME(6,0,0)) | F34: =D34-E34 | G34: 0 | H34: =F34-G34 | I34: =I33+H34
A35: 46056 | B35: =_xlfn.MINIFS(Atividades!$E:$E,Atividades!$A:$A, A35) | C35: =_xlfn.MAXIFS(Atividades!$F:$F, Atividades!$A:$A, A35) | D35: =IF(C35-B35>TIME(6,0,0), (C35-B35)-TIME(1,0,0), C35-B35) | E35: =IF(OR(D35<=0, B35="", C35=""), 0, TIME(6,0,0)) | F35: =D35-E35 | G35: 0 | H35: =F35-G35 | I35: =I34+H35
A36: 46057 | B36: =_xlfn.MINIFS(Atividades!$E:$E,Atividades!$A:$A, A36) | C36: =_xlfn.MAXIFS(Atividades!$F:$F, Atividades!$A:$A, A36) | D36: =IF(C36-B36>TIME(6,0,0), (C36-B36)-TIME(1,0,0), C36-B36) | E36: =IF(OR(D36<=0, B36="", C36=""), 0, TIME(6,0,0)) | F36: =D36-E36 | G36: 0 | H36: =F36-G36 | I36: =I35+H36
A37: 46058 | B37: =_xlfn.MINIFS(Atividades!$E:$E,Atividades!$A:$A, A37) | C37: =_xlfn.MAXIFS(Atividades!$F:$F, Atividades!$A:$A, A37) | D37: =IF(C37-B37>TIME(6,0,0), (C37-B37)-TIME(1,0,0), C37-B37) | E37: =IF(OR(D37<=0, B37="", C37=""), 0, TIME(6,0,0)) | F37: =D37-E37 | G37: 0 | H37: =F37-G37 | I37: =I36+H37
A38: 46059 | B38: =_xlfn.MINIFS(Atividades!$E:$E,Atividades!$A:$A, A38) | C38: =_xlfn.MAXIFS(Atividades!$F:$F, Atividades!$A:$A, A38) | D38: =IF(C38-B38>TIME(6,0,0), (C38-B38)-TIME(1,0,0), C38-B38) | E38: =IF(OR(D38<=0, B38="", C38=""), 0, TIME(6,0,0)) | F38: 0 | G38: 0.083333333 | H38: =F38-G38 | I38: =I37+H38
A39: 46064 | B39: =_xlfn.MINIFS(Atividades!$E:$E,Atividades!$A:$A, A39) | C39: =_xlfn.MAXIFS(Atividades!$F:$F, Atividades!$A:$A, A39) | D39: =IF(C39-B39>TIME(6,0,0), (C39-B39)-TIME(1,0,0), C39-B39) | E39: =IF(OR(D39<=0, B39="", C39=""), 0, TIME(6,0,0)) | F39: =D39-E39 | G39: 0 | H39: =F39-G39 | I39: =I38+H39
A40: 46065 | B40: =_xlfn.MINIFS(Atividades!$E:$E,Atividades!$A:$A, A40) | C40: =_xlfn.MAXIFS(Atividades!$F:$F, Atividades!$A:$A, A40) | D40: =IF(C40-B40>TIME(6,0,0), (C40-B40)-TIME(1,0,0), C40-B40) | E40: =IF(OR(D40<=0, B40="", C40=""), 0, TIME(6,0,0)) | F40: =D40-E40 | G40: 0 | H40: =F40-G40 | I40: =I39+H40
...
